Workbook

Sheet Live Dash
K1: =SUM(K5:K74) -> 0 | P1: =SUM(P5:P74) -> 0 | U1: =SUM(U5:U74) -> 0 | Z1: =SUM(Z5:Z74) -> 0 | AE1: =SUM(AE5:AE74) -> 0 | AJ1: =SUM(AJ5:AJ74) -> 0
B2: Running Position Dash | I2: Energy | N2: Agri | S2: Metals | X2: Softs | AC2: Livestock | AH2: Others
B4: {=_xlfn._xlws.FILTER(CHOOSE({1,2,3,4,5,6}, Mapping!C2:C1000,Mapping!D2:D1000, Mapping!M2:M1000, Mapping!N2:N1000, Mapping!O2:O1000, Mapping!P2:P1000), Mapping!N2:N1000<>0, "")} -> Contract | C4: Product | D4: Avg. Sell Price | E4: Open Pos. | F4: Running P/L | G4: Booked P/L | I4: Contract | J4: Open Pos. | K4: Running p/l | L4: Booked p/l | N4: Contract | O4: Open Pos. | P4: Running p/l | Q4: Booked p/l | S4: Contract | T4: Open Pos. | U4: Running p/l | V4: Booked p/l | X4: Contract | Y4: Open Pos. | Z4: Running p/l | AA4: Booked p/l | AC4: Contract | AD4: Open Pos. | AE4: Running p/l | AF4: Booked p/l | AH4: Contract | AI4: Open Pos. | AJ4: Running p/l | AK4: Booked p/l
B5: CL Aug25-Sep25 Calendar | C5: CL | D5: 1.59475 | E5: 2 | F5: 0 | G5: 1427.8049 | I5: {=_xlfn._xlws.FILTER( CHOOSE({1,2,3,4}, Mapping!C2:C1000, Mapping!N2:N1000, Mapping!O2:O1000, Mapping!P2:P1000), (Mapping!N2:N1000<>0) * (Mapping!U2:U1000=0) )} -> CL Aug25-Sep25 Calendar | J5: 2 | K5: 0 | L5: 1427.8049 | N5: {=_xlfn._xlws.FILTER( CHOOSE({1,2,3,4}, Mapping!C2:C1000, Mapping!N2:N1000, Mapping!O2:O1000, Mapping!P2:P1000), (Mapping!N2:N1000<>0) * (Mapping!U2:U1000=1) )} -> #VALUE! | S5: {=_xlfn._xlws.FILTER( CHOOSE({1,2,3,4}, Mapping!C2:C1000, Mapping!N2:N1000, Mapping!O2:O1000, Mapping!P2:P1000), (Mapping!N2:N1000<>0) * (Mapping!U2:U1000=2) )} -> #VALUE! | X5: {=_xlfn._xlws.FILTER( CHOOSE({1,2,3,4}, Mapping!C2:C1000, Mapping!N2:N1000, Mapping!O2:O1000, Mapping!P2:P1000), (Mapping!N2:N1000<>0) * (Mapping!U2:U1000=3) )} -> #VALUE! | AC5: {=_xlfn._xlws.FILTER( CHOOSE({1,2,3,4}, Mapping!C2:C1000, Mapping!N2:N1000, Mapping!O2:O1000, Mapping!P2:P1000), (Mapping!N2:N1000<>0) * (Mapping!U2:U1000=4) )} -> #VALUE! | AH5: {=_xlfn._xlws.FILTER( CHOOSE({1,2,3,4}, Mapping!C2:C1000, Mapping!N2:N1000, Mapping!O2:O1000, Mapping!P2:P1000), (Mapping!N2:N1000<>0) * (Mapping!U2:U1000=5) )} -> #VALUE!
B6: CL Sep25-Oct25 Calendar | C6: CL | D6: 1.3439286 | E6: 2 | F6: 0 | G6: 595.33333 | I6: CL Sep25-Oct25 Calendar | J6: 2 | K6: 0 | L6: 595.33333
B7: HO Sep25-Oct25 Calendar | C7: HO | D7: 0.019761538 | E7: 2 | F7: 0 | G7: 806.32 | I7: HO Sep25-Oct25 Calendar | J7: 2 | K7: 0 | L7: 806.32
B8: HO Aug25-Sep25 Calendar | C8: HO | D8: 0.023476923 | E8: 2 | F8: 0 | G8: -84.36 | I8: HO Aug25-Sep25 Calendar | J8: 2 | K8: 0 | L8: -84.36
B9: RB Sep25-Oct25 Calendar | C9: RB | D9: 0.1514 | E9: 4 | F9: 0 | G9: -66 | I9: RB Sep25-Oct25 Calendar | J9: 4 | K9: 0 | L9: -66
B10: NG Sep25-Oct25 Calendar | C10: NG | E10: 1 | F10: 0 | G10: 0 | I10: NG Sep25-Oct25 Calendar | J10: 1 | K10: 0 | L10: 0

Sheet Fill Book
A2: Datetime | B2: Date | C2: Time | D2: Exchange | E2: Contract | F2: Buy/Sell | G2: Lots | H2: Price
I3: XGKML_IFUS
B4: 45819 | C4: 0.70160396 | D4: CME | E4: ZL Jul25-Aug25 Calendar | F4: S | G4: 5 | H4: -0.18 | I4: F | J4: TT SIM | K4: XGVDO-SIM | L4: VDO-VSaini | M4: VDO-VSaini | N4: cf9c4c45-082e-48bb-baa2-a5bad607b471
B5: 45819 | C5: 0.70123687 | D5: CME | E5: ZL Jul25-Aug25 Calendar | F5: B | G5: 5 | H5: -0.17 | I5: F | J5: TT SIM | K5: XGVDO-SIM | L5: VDO-VSaini | M5: VDO-VSaini | N5: b35754e9-ae59-4ef5-b0f4-ece6a4914bce
B6: 45819 | C6: 0.70102175 | D6: CME | E6: ZL Jul25-Aug25 Calendar | F6: B | G6: 5 | H6: -0.17 | I6: F | J6: TT SIM | K6: XGVDO-SIM | L6: VDO-VSaini | M6: VDO-VSaini | N6: 4f7a076e-c339-4f42-936a-8d9c3dd14e94
B7: 45819 | C7: 0.67035417 | D7: CME | E7: ZL Jul25-Aug25 Calendar | F7: S | G7: 5 | H7: -0.17 | I7: F | J7: TT SIM | K7: XGVDO-SIM | L7: VDO-VSaini | M7: VDO-VSaini | N7: 4a61bcec-38b4-4125-ac0a-72cec67e5783
B8: 45819 | C8: 0.66995406 | D8: CME | E8: ZL Jul25-Aug25 Calendar | F8: B | G8: 5 | H8: -0.16 | I8: F | J8: TT SIM | K8: XGVDO-SIM | L8: VDO-VSaini | M8: VDO-VSaini | N8: 87ce652a-f409-4427-a71f-796caa7a2967
B9: 45819 | C9: 0.6044487 | D9: CME | E9: ZL Jul25-Aug25 Calendar | F9: S | G9: 5 | H9: -0.17 | I9: F | J9: TT SIM | K9: XGVDO-SIM | L9: VDO-VSaini | M9: VDO-VSaini | N9: 890a9b8e-2aa5-4d9f-b316-d636276aeb9b
B10: 45819 | C10: 0.48375456 | D10: CME | E10: CL Aug25-Sep25 Calendar | F10: S | G10: 2 | H10: 1.04 | I10: F | J10: TT SIM | K10: XGVDO-SIM | L10: VDO-VSaini | M10: VDO-VSaini | N10: d1cc9fe5-4c26-49f2-934f-b47ec9e43cfd
B11: 45819 | C11: 0.47439763 | D11: CME | E11: CL Aug25-Sep25 Calendar | F11: B | G11: 2 | H11: 1.04 | I11: F | J11: TT SIM | K11: XGVDO-SIM | L11: VDO-VSaini | M11: VDO-VSaini | N11: ac0a640b-c678-4dfa-8839-98c86ac58f9f
I12: XGKML
B13: 45820 | C13: 0.72635633 | D13: CME | E13: ZL Sep25-Oct25 Calendar | F13: B | G13: 5 | H13: -0.06 | I13: F | J13: TT SIM | K13: XGVDO-SIM | L13: VDO-VSaini | M13: VDO-VSaini | N13: d3c97965-4ce6-4f44-a570-00e11511e808
B14: 45820 | C14: 0.72351807 | D14: CME | E14: ZL Sep25-Oct25 Calendar | F14: B | G14: 3 | H14: -0.05 | I14: F | J14: TT SIM | K14: XGVDO-SIM | L14: VDO-VSaini | M14: VDO-VSaini | N14: d6b90dfe-1b8d-47e7-b74f-807f59d39892
B15: 45820 | C15: 0.72015141 | D15: CME | E15: ZL Sep25-Oct25 Calendar | F15: B | G15: 2 | H15: -0.04 | I15: F | J15: TT SIM | K15: XGVDO-SIM | L15: VDO-VSaini | M15: VDO-VSaini | N15: d4f54407-21eb-41cb-b5fd-d4df36f91a54
B16: 45820 | C16: 0.6827561 | D16: CME | E16: ZL Aug25-Sep25 Calendar | F16: B | G16: 10 | H16: -0.1 | I16: F | J16: TT SIM | K16: XGVDO-SIM | L16: VDO-VSaini | M16: VDO-VSaini | N16: 50c34416-b58f-4596-93cd-e629c730cb19
B17: 45820 | C17: 0.65529716 | D17: CME | E17: ZL Sep25-Oct25 Calendar | F17: S | G17: 10 | H17: -0.04 | I17: F | J17: Algo SE | K17: XGVDO-SIM | L17: VDO-VSaini | M17: VDO-VSaini | N17: 1a0424da-4e6c-4fa9-b777-ecc7933e7cf8
B18: 45820 | C18: 0.65180464 | D18: CME | E18: ZL Aug25-Sep25 Calendar | F18: S | G18: 10 | H18: -0.09 | I18: F | J18: TT SIM | K18: XGVDO-SIM | L18: VDO-VSaini | M18: VDO-VSaini | N18: 75e04b7f-7719-472b-bdf5-ea2913a5cb49
B19: 45820 | C19: 0.6516238 | D19: CME | E19: ZL Aug25-Sep25 Calendar | F19: B | G19: 10 | H19: -0.08 | I19: XGKML
B20: 45820 | C20: 0.65031828 | D20: CME | E20: ZL Aug25-Sep25 Calendar | F20: S | G20: 10 | H20: -0.09 | I20: XGKML
I21: F | J21: TT SIM | K21: XGVDO-SIM | L21: VDO-VSaini | M21: VDO-VSaini | N21: d5764e62-36bc-4aca-8ff1-281bed97227c
I22: F | J22: TT SIM | K22: XGVDO-SIM | L22: VDO-VSaini | M22: VDO-VSaini | N22: 065c2ff9-cccb-4ccf-8df9-cce3ff71d43a
I23: XGKML
B24: 45821 | C24: 0.5532089 | D24: CME | E24: CL Aug25-Sep25 Calendar | F24: S | G24: 5 | H24: 1.82 | I24: F | J24: TT SIM | K24: XGVDO-SIM | L24: VDO-VSaini | M24: VDO-VSaini | N24: 2968f61f-e771-4643-96a8-965845285018
B25: 45821 | C25: 0.55267792 | D25: CME | E25: CL Aug25-Sep25 Calendar | F25: S | G25: 5 | H25: 1.81 | I25: F | J25: TT SIM | K25: XGVDO-SIM | L25: VDO-VSaini | M25: VDO-VSaini | N25: 0560e90a-6c7b-4b8f-8824-62817e697b44
B26: 45821 | C26: 0.54640582 | D26: CME | E26: CL Aug25-Sep25 Calendar | F26: S | G26: 5 | H26: 1.82 | I26: F | J26: TT SIM | K26: XGVDO-SIM | L26: VDO-VSaini | M26: VDO-VSaini | N26: b67ae19e-c742-40fb-8e18-aab26394182e
B27: 45821 | C27: 0.54619396 | D27: CME | E27: CL Aug25-Sep25 Calendar | F27: B | G27: 5 | H27: 1.84 | I27: F | J27: TT SIM | K27: XGVDO-SIM | L27: VDO-VSaini | M27: VDO-VSaini | N27: 28bc1c2f-a388-4d80-a361-bc8523da15ac
B28: 45821 | C28: 0.54436603 | D28: CME* | E28: CL Aug25-Sep25 Calendar | F28: B | G28: 5 | H28: 1.8 | I28: F | J28: TT SIM | K28: XGVDO-SIM | L28: VDO-VSaini | M28: VDO-VSaini | N28: f0843980-d26d-4a56-953c-0c57a7bd5b25
B29: 45821 | C29: 0.54366679 | D29: CME | E29: CL Aug25-Sep25 Calendar | F29: B | G29: 5 | H29: 1.79 | I29: F | J29: TT SIM | K29: XGVDO-SIM | L29: VDO-VSaini | M29: VDO-VSaini | N29: b30d3bf4-6522-4b79-8ee7-7f532108e904
B30: 45821 | C30: 0.61707645 | D30: CME | E30: CL Aug25-Sep25 Calendar | F30: B | G30: 10 | H30: 1.66 | I30: P | J30: AOTC | K30: XGVDO-SIM | L30: VDO-VSaini | M30: VDO-VSaini | N30: 90b20edc-3044-4d95-bb42-99782ea9697b | P30: Transfer
B31: 45821 | C31: 0.60723331 | D31: CME | E31: CL Aug25-Sep25 Calendar | F31: S | G31: 10 | H31: 1.77 | I31: F | J31: TT SIM | K31: XGVDO-SIM | L31: VDO-VSaini | M31: VDO-VSaini | N31: b00bb0fa-e591-45bc-ab26-c4833e8ac6a4
I32: F | J32: TT SIM | K32: XGVDO-SIM | L32: VDO-VSaini | M32: VDO-VSaini | N32: dd7bfa9b-13d3-4b05-8238-c1ac1a74203d
B33: 45824 | C33: 0.63791956 | D33: CME | E33: HO Jul25-Aug25 Calendar | F33: B | G33: 2 | H33: 0.015 | I33: F | J33: TT SIM | K33: XGVDO-SIM | L33: VDO-VSaini | M33: VDO-VSaini | N33: ffa889a7-418e-4089-ac91-2599ab33ff38
B34: 45824 | C34: 0.63599714 | D34: CME | E34: HO Jul25-Aug25 Calendar | F34: S | G34: 2 | H34: 0.0152 | I34: F | J34: TT SIM | K34: XGVDO-SIM | L34: VDO-VSaini | M34: VDO-VSaini | N34: 3d00545a-0e6a-487a-b301-4349a866bfd4
B35: 45824 | C35: 0.62763183 | D35: CME | E35: CL Sep25-Oct25 Calendar | F35: S | G35: 10 | H35: 1.21 | I35: F | J35: TT SIM | K35: XGVDO-SIM | L35: VDO-VSaini | M35: VDO-VSaini | N35: eb8b9dc1-f526-4f95-af1b-4b719b4e75dc
B36: 45824 | C36: 0.62652006 | D36: CME | E36: CL Sep25-Oct25 Calendar | F36: B | G36: 10 | H36: 1.19 | I36: XGKML
B37: 45824 | C37: 0.62551899 | D37: CME | E37: CL Aug25-Sep25 Calendar | F37: B | G37: 10 | H37: 1.48 | I37: XGKML
B38: 45824 | C38: 0.62219209 | D38: CME | E38: CL Aug25-Sep25 Calendar | F38: S | G38: 10 | H38: 1.51 | I38: XGKML
B39: 45824 | C39: 0.62110569 | D39: CME | E39: CL Aug25-Sep25 Calendar | F39: S | G39: 1 | H39: 1.54 | I39: XGKML
B40: 45824 | C40: 0.62075075 | D40: CME | E40: CL Aug25-Sep25 Calendar | F40: S | G40: 5 | H40: 1.57 | I40: XGKML
B41: 45824 | C41: 0.61986049 | D41: CME | E41: CL Aug25-Sep25 Calendar | F41: S | G41: 1 | H41: 1.64 | I41: XGKML
...

Sheet Mapping
B2: Category | C2: Contract | D2: Product | E2: Tick Size | F2: Tick Value | G2: RT | H2: Exchange | I2: Last | J2: Buy Qty | K2: Avg. Buy Price | L2: Sell Qty | M2: Avg. Sell Price | N2: Open Pos. | O2: Running P/L | P2: Booked P/L | Q2: RT | R2: Avg Ticks Booked | S2: Stop Price | T2: Max Heat | U2: Asset Code | V2: Comm.
B3: ASE | C3: {=_xlfn.UNIQUE(_xlfn._xlws.FILTER('Fill Book'!E4:E9968, 'Fill Book'!E4:E9968 <> ""))} -> ZL Jul25-Aug25 Calendar | D3: {=UPPER(_xlfn.TEXTJOIN("", TRUE, IF(ISNUMBER(FIND(MID(LEFT(C3, FIND(" ", C3 & " ") - 1), ROW(INDIRECT("1:" & LEN(LEFT(C3, FIND(" ", C3 & " ") - 1)))), 1), "ABCDEFGHIJKLMNOPQRSTUVWXYZabcdefghijklmnopqrstuvwxyz")), MID(LEFT(C3, FIND(" ", C3 & " ") - 1), ROW(INDIRECT("1:" & LEN(LEFT(C3, FIND(" ", C3 & " ") - 1)))), 1), "")))} -> ZL | E3: =INDEX(Ref!C:C, MATCH(Mapping!D3, Ref!$B:$B,0)) -> 0.01 | F3: =INDEX(Ref!D:D, MATCH(Mapping!D3, Ref!$B:$B,0)) -> 6 | G3: {=IFERROR(_xlfn.SWITCH(LOWER(TRIM(RIGHT(SUBSTITUTE(C3," ",REPT(" ",99)),99))),"fly",4,"dfly",8,"calendar",2,"box",4,4),4)} -> 2 | H3: ASE | I3: =RTD("tt.rtd",,RTD("tt.rtd",,"Inst",H3,$C3),I$2) -> #N/A | J3: {=SUM(IF(('Fill Book'!$F$4:$F$10084="B")*('Fill Book'!$E$4:$E$10084=Mapping!C3),'Fill Book'!$G$4:$G$10084))} -> 15 | K3: {=IFERROR( SUMPRODUCT( ('Fill Book'!$F$4:$F$10084="B") * ('Fill Book'!$E$4:$E$10084=Mapping!C3), 'Fill Book'!$G$4:$G$10084, 'Fill Book'!$H$4:$H$10084 ) / SUMIFS( 'Fill Book'!$G$4:$G$10084, 'Fill Book'!$F$4:$F$10084, "B", 'Fill Book'!$E$4:$E$10084, Mapping!C3 ), "" )} -> -0.16666667 | L3: =SUMIFS('Fill Book'!$G$4:$G$10084, 'Fill Book'!$F$4:$F$10084, "S", 'Fill Book'!$E$4:$E$10084, Mapping!C3) -> 15 | M3: {=IFERROR( SUMPRODUCT( ('Fill Book'!$F$4:$F$10084="S") * ('Fill Book'!$E$4:$E$10084=Mapping!C3), 'Fill Book'!$G$4:$G$10084, 'Fill Book'!$H$4:$H$10084 ) / SUMIFS( 'Fill Book'!$G$4:$G$10084, 'Fill Book'!$F$4:$F$10084, "S", 'Fill Book'!$E$4:$E$10084, Mapping!C3 ), "" )} -> -0.17333333 | N3: =$J3-$L3 -> 0 | O3: =IFERROR( IF(L3 > J3, ((M3 - I3) / E3) * F3 * (L3 - J3), ((I3 - K3) / E3) * F3 * (J3 - L3) ), 0) -> 0 | P3: =IFERROR((MIN(J3,L3) * ((M3 - K3) / E3) * F3)-V3*Q3, 0) -> -105 | Q3: =MIN($J3,$L3)*$G3 -> 30 | R3: =((Mapping!$M3 - Mapping!$K3) / Mapping!$E3 * Mapping!$F3) * (MIN(Mapping!$J3, Mapping!$L3)) -> -60 | S3: =IFERROR(INDEX(#REF!, MATCH(Mapping!C3,#REF!, 0)), "") | T3: =IF(N3>0, (S3-K3)*F3/E3*N3, (S3-M3)*F3/E3*N3) -> #VALUE! | U3: =IFERROR(INDEX(Ref!E:E, MATCH(D3, Ref!B:B, 0)),5) -> 1 | V3: =IFERROR(INDEX(Ref!F:F, MATCH(D3, Ref!B:B, 0)),1.5) -> 1.5
C4: CL Aug25-Sep25 Calendar | D4: {=UPPER(_xlfn.TEXTJOIN("", TRUE, IF(ISNUMBER(FIND(MID(LEFT(C4, FIND(" ", C4 & " ") - 1), ROW(INDIRECT("1:" & LEN(LEFT(C4, FIND(" ", C4 & " ") - 1)))), 1), "ABCDEFGHIJKLMNOPQRSTUVWXYZabcdefghijklmnopqrstuvwxyz")), MID(LEFT(C4, FIND(" ", C4 & " ") - 1), ROW(INDIRECT("1:" & LEN(LEFT(C4, FIND(" ", C4 & " ") - 1)))), 1), "")))} -> CL | E4: =INDEX(Ref!C:C, MATCH(Mapping!D4, Ref!$B:$B,0)) -> 0.01 | F4: =INDEX(Ref!D:D, MATCH(Mapping!D4, Ref!$B:$B,0)) -> 10 | G4: {=IFERROR(_xlfn.SWITCH(LOWER(TRIM(RIGHT(SUBSTITUTE(C4," ",REPT(" ",99)),99))),"fly",4,"dfly",8,"calendar",2,"box",4,4),4)} -> 2 | H4: ASE | I4: =RTD("tt.rtd",,RTD("tt.rtd",,"Inst",H4,$C4),I$2) -> #N/A | J4: {=SUM(IF(('Fill Book'!$F$4:$F$10084="B")*('Fill Book'!$E$4:$E$10084=Mapping!C4),'Fill Book'!$G$4:$G$10084))} -> 82 | K4: {=IFERROR( SUMPRODUCT( ('Fill Book'!$F$4:$F$10084="B") * ('Fill Book'!$E$4:$E$10084=Mapping!C4), 'Fill Book'!$G$4:$G$10084, 'Fill Book'!$H$4:$H$10084 ) / SUMIFS( 'Fill Book'!$G$4:$G$10084, 'Fill Book'!$F$4:$F$10084, "B", 'Fill Book'!$E$4:$E$10084, Mapping!C4 ), "" )} -> 1.5739024 | L4: =SUMIFS('Fill Book'!$G$4:$G$10084, 'Fill Book'!$F$4:$F$10084, "S", 'Fill Book'!$E$4:$E$10084, Mapping!C4) -> 80 | M4: {=IFERROR( SUMPRODUCT( ('Fill Book'!$F$4:$F$10084="S") * ('Fill Book'!$E$4:$E$10084=Mapping!C4), 'Fill Book'!$G$4:$G$10084, 'Fill Book'!$H$4:$H$10084 ) / SUMIFS( 'Fill Book'!$G$4:$G$10084, 'Fill Book'!$F$4:$F$10084, "S", 'Fill Book'!$E$4:$E$10084, Mapping!C4 ), "" )} -> 1.59475 | N4: =$J4-$L4 -> 2 | O4: =IFERROR( IF(L4 > J4, ((M4 - I4) / E4) * F4 * (L4 - J4), ((I4 - K4) / E4) * F4 * (J4 - L4) ), 0) -> 0 | P4: =IFERROR((MIN(J4,L4) * ((M4 - K4) / E4) * F4)-V4*Q4, 0) -> 1427.8049 | Q4: =MIN($J4,$L4)*$G4 -> 160 | R4: =((Mapping!$M4 - Mapping!$K4) / Mapping!$E4 * Mapping!$F4) * (MIN(Mapping!$J4, Mapping!$L4)) -> 1667.8049 | S4: =IFERROR(INDEX(#REF!, MATCH(Mapping!C4,#REF!, 0)), "") | T4: =IF(N4>0, (S4-K4)*F4/E4*N4, (S4-M4)*F4/E4*N4) -> #VALUE! | U4: =IFERROR(INDEX(Ref!E:E, MATCH(D4, Ref!B:B, 0)),5) -> 0 | V4: =IFERROR(INDEX(Ref!F:F, MATCH(D4, Ref!B:B, 0)),1.5) -> 1.5
C5: ZL Sep25-Oct25 Calendar | D5: {=UPPER(_xlfn.TEXTJOIN("", TRUE, IF(ISNUMBER(FIND(MID(LEFT(C5, FIND(" ", C5 & " ") - 1), ROW(INDIRECT("1:" & LEN(LEFT(C5, FIND(" ", C5 & " ") - 1)))), 1), "ABCDEFGHIJKLMNOPQRSTUVWXYZabcdefghijklmnopqrstuvwxyz")), MID(LEFT(C5, FIND(" ", C5 & " ") - 1), ROW(INDIRECT("1:" & LEN(LEFT(C5, FIND(" ", C5 & " ") - 1)))), 1), "")))} -> ZL | E5: =INDEX(Ref!C:C, MATCH(Mapping!D5, Ref!$B:$B,0)) -> 0.01 | F5: =INDEX(Ref!D:D, MATCH(Mapping!D5, Ref!$B:$B,0)) -> 6 | G5: {=IFERROR(_xlfn.SWITCH(LOWER(TRIM(RIGHT(SUBSTITUTE(C5," ",REPT(" ",99)),99))),"fly",4,"dfly",8,"calendar",2,"box",4,4),4)} -> 2 | H5: ASE | I5: =RTD("tt.rtd",,RTD("tt.rtd",,"Inst",H5,$C5),I$2) -> #N/A | J5: {=SUM(IF(('Fill Book'!$F$4:$F$10084="B")*('Fill Book'!$E$4:$E$10084=Mapping!C5),'Fill Book'!$G$4:$G$10084))} -> 10 | K5: {=IFERROR( SUMPRODUCT( ('Fill Book'!$F$4:$F$10084="B") * ('Fill Book'!$E$4:$E$10084=Mapping!C5), 'Fill Book'!$G$4:$G$10084, 'Fill Book'!$H$4:$H$10084 ) / SUMIFS( 'Fill Book'!$G$4:$G$10084, 'Fill Book'!$F$4:$F$10084, "B", 'Fill Book'!$E$4:$E$10084, Mapping!C5 ), "" )} -> -0.053 | L5: =SUMIFS('Fill Book'!$G$4:$G$10084, 'Fill Book'!$F$4:$F$10084, "S", 'Fill Book'!$E$4:$E$10084, Mapping!C5) -> 10 | M5: {=IFERROR( SUMPRODUCT( ('Fill Book'!$F$4:$F$10084="S") * ('Fill Book'!$E$4:$E$10084=Mapping!C5), 'Fill Book'!$G$4:$G$10084, 'Fill Book'!$H$4:$H$10084 ) / SUMIFS( 'Fill Book'!$G$4:$G$10084, 'Fill Book'!$F$4:$F$10084, "S", 'Fill Book'!$E$4:$E$10084, Mapping!C5 ), "" )} -> -0.04 | N5: =$J5-$L5 -> 0 | O5: =IFERROR( IF(L5 > J5, ((M5 - I5) / E5) * F5 * (L5 - J5), ((I5 - K5) / E5) * F5 * (J5 - L5) ), 0) -> 0 | P5: =IFERROR((MIN(J5,L5) * ((M5 - K5) / E5) * F5)-V5*Q5, 0) -> 48 | Q5: =MIN($J5,$L5)*$G5 -> 20 | R5: =((Mapping!$M5 - Mapping!$K5) / Mapping!$E5 * Mapping!$F5) * (MIN(Mapping!$J5, Mapping!$L5)) -> 78 | S5: =IFERROR(INDEX(#REF!, MATCH(Mapping!C5,#REF!, 0)), "") | T5: =IF(N5>0, (S5-K5)*F5/E5*N5, (S5-M5)*F5/E5*N5) -> #VALUE! | U5: =IFERROR(INDEX(Ref!E:E, MATCH(D5, Ref!B:B, 0)),5) -> 1 | V5: =IFERROR(INDEX(Ref!F:F, MATCH(D5, Ref!B:B, 0)),1.5) -> 1.5
C6: ZL Aug25-Sep25 Calendar | D6: {=UPPER(_xlfn.TEXTJOIN("", TRUE, IF(ISNUMBER(FIND(MID(LEFT(C6, FIND(" ", C6 & " ") - 1), ROW(INDIRECT("1:" & LEN(LEFT(C6, FIND(" ", C6 & " ") - 1)))), 1), "ABCDEFGHIJKLMNOPQRSTUVWXYZabcdefghijklmnopqrstuvwxyz")), MID(LEFT(C6, FIND(" ", C6 & " ") - 1), ROW(INDIRECT("1:" & LEN(LEFT(C6, FIND(" ", C6 & " ") - 1)))), 1), "")))} -> ZL | E6: =INDEX(Ref!C:C, MATCH(Mapping!D6, Ref!$B:$B,0)) -> 0.01 | F6: =INDEX(Ref!D:D, MATCH(Mapping!D6, Ref!$B:$B,0)) -> 6 | G6: {=IFERROR(_xlfn.SWITCH(LOWER(TRIM(RIGHT(SUBSTITUTE(C6," ",REPT(" ",99)),99))),"fly",4,"dfly",8,"calendar",2,"box",4,4),4)} -> 2 | H6: ASE | I6: =RTD("tt.rtd",,RTD("tt.rtd",,"Inst",H6,$C6),I$2) -> #N/A | J6: {=SUM(IF(('Fill Book'!$F$4:$F$10084="B")*('Fill Book'!$E$4:$E$10084=Mapping!C6),'Fill Book'!$G$4:$G$10084))} -> 20 | K6: {=IFERROR( SUMPRODUCT( ('Fill Book'!$F$4:$F$10084="B") * ('Fill Book'!$E$4:$E$10084=Mapping!C6), 'Fill Book'!$G$4:$G$10084, 'Fill Book'!$H$4:$H$10084 ) / SUMIFS( 'Fill Book'!$G$4:$G$10084, 'Fill Book'!$F$4:$F$10084, "B", 'Fill Book'!$E$4:$E$10084, Mapping!C6 ), "" )} -> -0.09 | L6: =SUMIFS('Fill Book'!$G$4:$G$10084, 'Fill Book'!$F$4:$F$10084, "S", 'Fill Book'!$E$4:$E$10084, Mapping!C6) -> 20 | M6: {=IFERROR( SUMPRODUCT( ('Fill Book'!$F$4:$F$10084="S") * ('Fill Book'!$E$4:$E$10084=Mapping!C6), 'Fill Book'!$G$4:$G$10084, 'Fill Book'!$H$4:$H$10084 ) / SUMIFS( 'Fill Book'!$G$4:$G$10084, 'Fill Book'!$F$4:$F$10084, "S", 'Fill Book'!$E$4:$E$10084, Mapping!C6 ), "" )} -> -0.09 | N6: =$J6-$L6 -> 0 | O6: =IFERROR( IF(L6 > J6, ((M6 - I6) / E6) * F6 * (L6 - J6), ((I6 - K6) / E6) * F6 * (J6 - L6) ), 0) -> 0 | P6: =IFERROR((MIN(J6,L6) * ((M6 - K6) / E6) * F6)-V6*Q6, 0) -> -60 | Q6: =MIN($J6,$L6)*$G6 -> 40 | R6: =((Mapping!$M6 - Mapping!$K6) / Mapping!$E6 * Mapping!$F6) * (MIN(Mapping!$J6, Mapping!$L6)) -> 0 | S6: =IFERROR(INDEX(#REF!, MATCH(Mapping!C6,#REF!, 0)), "") | T6: =IF(N6>0, (S6-K6)*F6/E6*N6, (S6-M6)*F6/E6*N6) -> #VALUE! | U6: =IFERROR(INDEX(Ref!E:E, MATCH(D6, Ref!B:B, 0)),5) -> 1 | V6: =IFERROR(INDEX(Ref!F:F, MATCH(D6, Ref!B:B, 0)),1.5) -> 1.5
C7: HO Jul25-Aug25 Calendar | D7: {=UPPER(_xlfn.TEXTJOIN("", TRUE, IF(ISNUMBER(FIND(MID(LEFT(C7, FIND(" ", C7 & " ") - 1), ROW(INDIRECT("1:" & LEN(LEFT(C7, FIND(" ", C7 & " ") - 1)))), 1), "ABCDEFGHIJKLMNOPQRSTUVWXYZabcdefghijklmnopqrstuvwxyz")), MID(LEFT(C7, FIND(" ", C7 & " ") - 1), ROW(INDIRECT("1:" & LEN(LEFT(C7, FIND(" ", C7 & " ") - 1)))), 1), "")))} -> HO | E7: =INDEX(Ref!C:C, MATCH(Mapping!D7, Ref!$B:$B,0)) -> 0.0001 | F7: =INDEX(Ref!D:D, MATCH(Mapping!D7, Ref!$B:$B,0)) -> 4.2 | G7: {=IFERROR(_xlfn.SWITCH(LOWER(TRIM(RIGHT(SUBSTITUTE(C7," ",REPT(" ",99)),99))),"fly",4,"dfly",8,"calendar",2,"box",4,4),4)} -> 2 | H7: ASE | I7: =RTD("tt.rtd",,RTD("tt.rtd",,"Inst",H7,$C7),I$2) -> #N/A | J7: {=SUM(IF(('Fill Book'!$F$4:$F$10084="B")*('Fill Book'!$E$4:$E$10084=Mapping!C7),'Fill Book'!$G$4:$G$10084))} -> 21 | K7: {=IFERROR( SUMPRODUCT( ('Fill Book'!$F$4:$F$10084="B") * ('Fill Book'!$E$4:$E$10084=Mapping!C7), 'Fill Book'!$G$4:$G$10084, 'Fill Book'!$H$4:$H$10084 ) / SUMIFS( 'Fill Book'!$G$4:$G$10084, 'Fill Book'!$F$4:$F$10084, "B", 'Fill Book'!$E$4:$E$10084, Mapping!C7 ), "" )} -> 0.03072381 | L7: =SUMIFS('Fill Book'!$G$4:$G$10084, 'Fill Book'!$F$4:$F$10084, "S", 'Fill Book'!$E$4:$E$10084, Mapping!C7) -> 21 | M7: {=IFERROR( SUMPRODUCT( ('Fill Book'!$F$4:$F$10084="S") * ('Fill Book'!$E$4:$E$10084=Mapping!C7), 'Fill Book'!$G$4:$G$10084, 'Fill Book'!$H$4:$H$10084 ) / SUMIFS( 'Fill Book'!$G$4:$G$10084, 'Fill Book'!$F$4:$F$10084, "S", 'Fill Book'!$E$4:$E$10084, Mapping!C7 ), "" )} -> 0.030728571 | N7: =$J7-$L7 -> 0 | O7: =IFERROR( IF(L7 > J7, ((M7 - I7) / E7) * F7 * (L7 - J7), ((I7 - K7) / E7) * F7 * (J7 - L7) ), 0) -> 0 | P7: =IFERROR((MIN(J7,L7) * ((M7 - K7) / E7) * F7)-V7*Q7, 0) -> -58.8 | Q7: =MIN($J7,$L7)*$G7 -> 42 | R7: =((Mapping!$M7 - Mapping!$K7) / Mapping!$E7 * Mapping!$F7) * (MIN(Mapping!$J7, Mapping!$L7)) -> 4.2 | S7: =IFERROR(INDEX(#REF!, MATCH(Mapping!C7,#REF!, 0)), "") | T7: =IF(N7>0, (S7-K7)*F7/E7*N7, (S7-M7)*F7/E7*N7) -> #VALUE! | U7: =IFERROR(INDEX(Ref!E:E, MATCH(D7, Ref!B:B, 0)),5) -> 0 | V7: =IFERROR(INDEX(Ref!F:F, MATCH(D7, Ref!B:B, 0)),1.5) -> 1.5
C8: CL Sep25-Oct25 Calendar | D8: {=UPPER(_xlfn.TEXTJOIN("", TRUE, IF(ISNUMBER(FIND(MID(LEFT(C8, FIND(" ", C8 & " ") - 1), ROW(INDIRECT("1:" & LEN(LEFT(C8, FIND(" ", C8 & " ") - 1)))), 1), "ABCDEFGHIJKLMNOPQRSTUVWXYZabcdefghijklmnopqrstuvwxyz")), MID(LEFT(C8, FIND(" ", C8 & " ") - 1), ROW(INDIRECT("1:" & LEN(LEFT(C8, FIND(" ", C8 & " ") - 1)))), 1), "")))} -> CL | E8: =INDEX(Ref!C:C, MATCH(Mapping!D8, Ref!$B:$B,0)) -> 0.01 | F8: =INDEX(Ref!D:D, MATCH(Mapping!D8, Ref!$B:$B,0)) -> 10 | G8: {=IFERROR(_xlfn.SWITCH(LOWER(TRIM(RIGHT(SUBSTITUTE(C8," ",REPT(" ",99)),99))),"fly",4,"dfly",8,"calendar",2,"box",4,4),4)} -> 2 | H8: ASE | I8: =RTD("tt.rtd",,RTD("tt.rtd",,"Inst",H8,$C8),I$2) -> #N/A | J8: {=SUM(IF(('Fill Book'!$F$4:$F$10084="B")*('Fill Book'!$E$4:$E$10084=Mapping!C8),'Fill Book'!$G$4:$G$10084))} -> 30 | K8: {=IFERROR( SUMPRODUCT( ('Fill Book'!$F$4:$F$10084="B") * ('Fill Book'!$E$4:$E$10084=Mapping!C8), 'Fill Book'!$G$4:$G$10084, 'Fill Book'!$H$4:$H$10084 ) / SUMIFS( 'Fill Book'!$G$4:$G$10084, 'Fill Book'!$F$4:$F$10084, "B", 'Fill Book'!$E$4:$E$10084, Mapping!C8 ), "" )} -> 1.3196667 | L8: =SUMIFS('Fill Book'!$G$4:$G$10084, 'Fill Book'!$F$4:$F$10084, "S", 'Fill Book'!$E$4:$E$10084, Mapping!C8) -> 28 | M8: {=IFERROR( SUMPRODUCT( ('Fill Book'!$F$4:$F$10084="S") * ('Fill Book'!$E$4:$E$10084=Mapping!C8), 'Fill Book'!$G$4:$G$10084, 'Fill Book'!$H$4:$H$10084 ) / SUMIFS( 'Fill Book'!$G$4:$G$10084, 'Fill Book'!$F$4:$F$10084, "S", 'Fill Book'!$E$4:$E$10084, Mapping!C8 ), "" )} -> 1.3439286 | N8: =$J8-$L8 -> 2 | O8: =IFERROR( IF(L8 > J8, ((M8 - I8) / E8) * F8 * (L8 - J8), ((I8 - K8) / E8) * F8 * (J8 - L8) ), 0) -> 0 | P8: =IFERROR((MIN(J8,L8) * ((M8 - K8) / E8) * F8)-V8*Q8, 0) -> 595.33333 | Q8: =MIN($J8,$L8)*$G8 -> 56 | R8: =((Mapping!$M8 - Mapping!$K8) / Mapping!$E8 * Mapping!$F8) * (MIN(Mapping!$J8, Mapping!$L8)) -> 679.33333 | S8: =IFERROR(INDEX(#REF!, MATCH(Mapping!C8,#REF!, 0)), "") | T8: =IF(N8>0, (S8-K8)*F8/E8*N8, (S8-M8)*F8/E8*N8) -> #VALUE! | U8: =IFERROR(INDEX(Ref!E:E, MATCH(D8, Ref!B:B, 0)),5) -> 0 | V8: =IFERROR(INDEX(Ref!F:F, MATCH(D8, Ref!B:B, 0)),1.5) -> 1.5
C9: HO Sep25-Oct25 Calendar | D9: {=UPPER(_xlfn.TEXTJOIN("", TRUE, IF(ISNUMBER(FIND(MID(LEFT(C9, FIND(" ", C9 & " ") - 1), ROW(INDIRECT("1:" & LEN(LEFT(C9, FIND(" ", C9 & " ") - 1)))), 1), "ABCDEFGHIJKLMNOPQRSTUVWXYZabcdefghijklmnopqrstuvwxyz")), MID(LEFT(C9, FIND(" ", C9 & " ") - 1), ROW(INDIRECT("1:" & LEN(LEFT(C9, FIND(" ", C9 & " ") - 1)))), 1), "")))} -> HO | E9: =INDEX(Ref!C:C, MATCH(Mapping!D9, Ref!$B:$B,0)) -> 0.0001 | F9: =INDEX(Ref!D:D, MATCH(Mapping!D9, Ref!$B:$B,0)) -> 4.2 | G9: {=IFERROR(_xlfn.SWITCH(LOWER(TRIM(RIGHT(SUBSTITUTE(C9," ",REPT(" ",99)),99))),"fly",4,"dfly",8,"calendar",2,"box",4,4),4)} -> 2 | H9: ASE | I9: =RTD("tt.rtd",,RTD("tt.rtd",,"Inst",H9,$C9),I$2) -> #N/A | J9: {=SUM(IF(('Fill Book'!$F$4:$F$10084="B")*('Fill Book'!$E$4:$E$10084=Mapping!C9),'Fill Book'!$G$4:$G$10084))} -> 15 | K9: {=IFERROR( SUMPRODUCT( ('Fill Book'!$F$4:$F$10084="B") * ('Fill Book'!$E$4:$E$10084=Mapping!C9), 'Fill Book'!$G$4:$G$10084, 'Fill Book'!$H$4:$H$10084 ) / SUMIFS( 'Fill Book'!$G$4:$G$10084, 'Fill Book'!$F$4:$F$10084, "B", 'Fill Book'!$E$4:$E$10084, Mapping!C9 ), "" )} -> 0.018213333 | L9: =SUMIFS('Fill Book'!$G$4:$G$10084, 'Fill Book'!$F$4:$F$10084, "S", 'Fill Book'!$E$4:$E$10084, Mapping!C9) -> 13 | M9: {=IFERROR( SUMPRODUCT( ('Fill Book'!$F$4:$F$10084="S") * ('Fill Book'!$E$4:$E$10084=Mapping!C9), 'Fill Book'!$G$4:$G$10084, 'Fill Book'!$H$4:$H$10084 ) / SUMIFS( 'Fill Book'!$G$4:$G$10084, 'Fill Book'!$F$4:$F$10084, "S", 'Fill Book'!$E$4:$E$10084, Mapping!C9 ), "" )} -> 0.019761538 | N9: =$J9-$L9 -> 2 | O9: =IFERROR( IF(L9 > J9, ((M9 - I9) / E9) * F9 * (L9 - J9), ((I9 - K9) / E9) * F9 * (J9 - L9) ), 0) -> 0 | P9: =IFERROR((MIN(J9,L9) * ((M9 - K9) / E9) * F9)-V9*Q9, 0) -> 806.32 | Q9: =MIN($J9,$L9)*$G9 -> 26 | R9: =((Mapping!$M9 - Mapping!$K9) / Mapping!$E9 * Mapping!$F9) * (MIN(Mapping!$J9, Mapping!$L9)) -> 845.32 | S9: =IFERROR(INDEX(#REF!, MATCH(Mapping!C9,#REF!, 0)), "") | T9: =IF(N9>0, (S9-K9)*F9/E9*N9, (S9-M9)*F9/E9*N9) -> #VALUE! | U9: =IFERROR(INDEX(Ref!E:E, MATCH(D9, Ref!B:B, 0)),5) -> 0 | V9: =IFERROR(INDEX(Ref!F:F, MATCH(D9, Ref!B:B, 0)),1.5) -> 1.5
C10: HO Aug25-Sep25 Calendar | D10: {=UPPER(_xlfn.TEXTJOIN("", TRUE, IF(ISNUMBER(FIND(MID(LEFT(C10, FIND(" ", C10 & " ") - 1), ROW(INDIRECT("1:" & LEN(LEFT(C10, FIND(" ", C10 & " ") - 1)))), 1), "ABCDEFGHIJKLMNOPQRSTUVWXYZabcdefghijklmnopqrstuvwxyz")), MID(LEFT(C10, FIND(" ", C10 & " ") - 1), ROW(INDIRECT("1:" & LEN(LEFT(C10, FIND(" ", C10 & " ") - 1)))), 1), "")))} -> HO | E10: =INDEX(Ref!C:C, MATCH(Mapping!D10, Ref!$B:$B,0)) -> 0.0001 | F10: =INDEX(Ref!D:D, MATCH(Mapping!D10, Ref!$B:$B,0)) -> 4.2 | G10: {=IFERROR(_xlfn.SWITCH(LOWER(TRIM(RIGHT(SUBSTITUTE(C10," ",REPT(" ",99)),99))),"fly",4,"dfly",8,"calendar",2,"box",4,4),4)} -> 2 | H10: ASE | I10: =RTD("tt.rtd",,RTD("tt.rtd",,"Inst",H10,$C10),I$2) -> #N/A | J10: {=SUM(IF(('Fill Book'!$F$4:$F$10084="B")*('Fill Book'!$E$4:$E$10084=Mapping!C10),'Fill Book'!$G$4:$G$10084))} -> 15 | K10: {=IFERROR( SUMPRODUCT( ('Fill Book'!$F$4:$F$10084="B") * ('Fill Book'!$E$4:$E$10084=Mapping!C10), 'Fill Book'!$G$4:$G$10084, 'Fill Book'!$H$4:$H$10084 ) / SUMIFS( 'Fill Book'!$G$4:$G$10084, 'Fill Book'!$F$4:$F$10084, "B", 'Fill Book'!$E$4:$E$10084, Mapping!C10 ), "" )} -> 0.02356 | L10: =SUMIFS('Fill Book'!$G$4:$G$10084, 'Fill Book'!$F$4:$F$10084, "S", 'Fill Book'!$E$4:$E$10084, Mapping!C10) -> 13 | M10: {=IFERROR( SUMPRODUCT( ('Fill Book'!$F$4:$F$10084="S") * ('Fill Book'!$E$4:$E$10084=Mapping!C10), 'Fill Book'!$G$4:$G$10084, 'Fill Book'!$H$4:$H$10084 ) / SUMIFS( 'Fill Book'!$G$4:$G$10084, 'Fill Book'!$F$4:$F$10084, "S", 'Fill Book'!$E$4:$E$10084, Mapping!C10 ), "" )} -> 0.023476923 | N10: =$J10-$L10 -> 2 | O10: =IFERROR( IF(L10 > J10, ((M10 - I10) / E10) * F10 * (L10 - J10), ((I10 - K10) / E10) * F10 * (J10 - L10) ), 0) -> 0 | P10: =IFERROR((MIN(J10,L10) * ((M10 - K10) / E10) * F10)-V10*Q10, 0) -> -84.36 | Q10: =MIN($J10,$L10)*$G10 -> 26 | R10: =((Mapping!$M10 - Mapping!$K10) / Mapping!$E10 * Mapping!$F10) * (MIN(Mapping!$J10, Mapping!$L10)) -> -45.36 | S10: =IFERROR(INDEX(#REF!, MATCH(Mapping!C10,#REF!, 0)), "") | T10: =IF(N10>0, (S10-K10)*F10/E10*N10, (S10-M10)*F10/E10*N10) -> #VALUE! | U10: =IFERROR(INDEX(Ref!E:E, MATCH(D10, Ref!B:B, 0)),5) -> 0 | V10: =IFERROR(INDEX(Ref!F:F, MATCH(D10, Ref!B:B, 0)),1.5) -> 1.5
C11: RB Sep25-Oct25 Calendar | D11: {=UPPER(_xlfn.TEXTJOIN("", TRUE, IF(ISNUMBER(FIND(MID(LEFT(C11, FIND(" ", C11 & " ") - 1), ROW(INDIRECT("1:" & LEN(LEFT(C11, FIND(" ", C11 & " ") - 1)))), 1), "ABCDEFGHIJKLMNOPQRSTUVWXYZabcdefghijklmnopqrstuvwxyz")), MID(LEFT(C11, FIND(" ", C11 & " ") - 1), ROW(INDIRECT("1:" & LEN(LEFT(C11, FIND(" ", C11 & " ") - 1)))), 1), "")))} -> RB | E11: =INDEX(Ref!C:C, MATCH(Mapping!D11, Ref!$B:$B,0)) -> 0.0001 | F11: =INDEX(Ref!D:D, MATCH(Mapping!D11, Ref!$B:$B,0)) -> 4.2 | G11: {=IFERROR(_xlfn.SWITCH(LOWER(TRIM(RIGHT(SUBSTITUTE(C11," ",REPT(" ",99)),99))),"fly",4,"dfly",8,"calendar",2,"box",4,4),4)} -> 2 | H11: ASE | I11: =RTD("tt.rtd",,RTD("tt.rtd",,"Inst",H11,$C11),I$2) -> #N/A | J11: {=SUM(IF(('Fill Book'!$F$4:$F$10084="B")*('Fill Book'!$E$4:$E$10084=Mapping!C11),'Fill Book'!$G$4:$G$10084))} -> 14 | K11: {=IFERROR( SUMPRODUCT( ('Fill Book'!$F$4:$F$10084="B") * ('Fill Book'!$E$4:$E$10084=Mapping!C11), 'Fill Book'!$G$4:$G$10084, 'Fill Book'!$H$4:$H$10084 ) / SUMIFS( 'Fill Book'!$G$4:$G$10084, 'Fill Book'!$F$4:$F$10084, "B", 'Fill Book'!$E$4:$E$10084, Mapping!C11 ), "" )} -> 0.15148571 | L11: =SUMIFS('Fill Book'!$G$4:$G$10084, 'Fill Book'!$F$4:$F$10084, "S", 'Fill Book'!$E$4:$E$10084, Mapping!C11) -> 10 | M11: {=IFERROR( SUMPRODUCT( ('Fill Book'!$F$4:$F$10084="S") * ('Fill Book'!$E$4:$E$10084=Mapping!C11), 'Fill Book'!$G$4:$G$10084, 'Fill Book'!$H$4:$H$10084 ) / SUMIFS( 'Fill Book'!$G$4:$G$10084, 'Fill Book'!$F$4:$F$10084, "S", 'Fill Book'!$E$4:$E$10084, Mapping!C11 ), "" )} -> 0.1514 | N11: =$J11-$L11 -> 4 | O11: =IFERROR( IF(L11 > J11, ((M11 - I11) / E11) * F11 * (L11 - J11), ((I11 - K11) / E11) * F11 * (J11 - L11) ), 0) -> 0 | P11: =IFERROR((MIN(J11,L11) * ((M11 - K11) / E11) * F11)-V11*Q11, 0) -> -66 | Q11: =MIN($J11,$L11)*$G11 -> 20 | R11: =((Mapping!$M11 - Mapping!$K11) / Mapping!$E11 * Mapping!$F11) * (MIN(Mapping!$J11, Mapping!$L11)) -> -36 | S11: =IFERROR(INDEX(#REF!, MATCH(Mapping!C11,#REF!, 0)), "") | T11: =IF(N11>0, (S11-K11)*F11/E11*N11, (S11-M11)*F11/E11*N11) -> #VALUE! | U11: =IFERROR(INDEX(Ref!E:E, MATCH(D11, Ref!B:B, 0)),5) -> 0 | V11: =IFERROR(INDEX(Ref!F:F, MATCH(D11, Ref!B:B, 0)),1.5) -> 1.5
C12: RB Aug25-Sep25 Calendar | D12: {=UPPER(_xlfn.TEXTJOIN("", TRUE, IF(ISNUMBER(FIND(MID(LEFT(C12, FIND(" ", C12 & " ") - 1), ROW(INDIRECT("1:" & LEN(LEFT(C12, FIND(" ", C12 & " ") - 1)))), 1), "ABCDEFGHIJKLMNOPQRSTUVWXYZabcdefghijklmnopqrstuvwxyz")), MID(LEFT(C12, FIND(" ", C12 & " ") - 1), ROW(INDIRECT("1:" & LEN(LEFT(C12, FIND(" ", C12 & " ") - 1)))), 1), "")))} -> RB | E12: =INDEX(Ref!C:C, MATCH(Mapping!D12, Ref!$B:$B,0)) -> 0.0001 | F12: =INDEX(Ref!D:D, MATCH(Mapping!D12, Ref!$B:$B,0)) -> 4.2 | G12: {=IFERROR(_xlfn.SWITCH(LOWER(TRIM(RIGHT(SUBSTITUTE(C12," ",REPT(" ",99)),99))),"fly",4,"dfly",8,"calendar",2,"box",4,4),4)} -> 2 | H12: ASE | I12: =RTD("tt.rtd",,RTD("tt.rtd",,"Inst",H12,$C12),I$2) -> #N/A | J12: {=SUM(IF(('Fill Book'!$F$4:$F$10084="B")*('Fill Book'!$E$4:$E$10084=Mapping!C12),'Fill Book'!$G$4:$G$10084))} -> 12 | K12: {=IFERROR( SUMPRODUCT( ('Fill Book'!$F$4:$F$10084="B") * ('Fill Book'!$E$4:$E$10084=Mapping!C12), 'Fill Book'!$G$4:$G$10084, 'Fill Book'!$H$4:$H$10084 ) / SUMIFS( 'Fill Book'!$G$4:$G$10084, 'Fill Book'!$F$4:$F$10084, "B", 'Fill Book'!$E$4:$E$10084, Mapping!C12 ), "" )} -> 0.031208333 | L12: =SUMIFS('Fill Book'!$G$4:$G$10084, 'Fill Book'!$F$4:$F$10084, "S", 'Fill Book'!$E$4:$E$10084, Mapping!C12) -> 12 | M12: {=IFERROR( SUMPRODUCT( ('Fill Book'!$F$4:$F$10084="S") * ('Fill Book'!$E$4:$E$10084=Mapping!C12), 'Fill Book'!$G$4:$G$10084, 'Fill Book'!$H$4:$H$10084 ) / SUMIFS( 'Fill Book'!$G$4:$G$10084, 'Fill Book'!$F$4:$F$10084, "S", 'Fill Book'!$E$4:$E$10084, Mapping!C12 ), "" )} -> 0.032566667 | N12: =$J12-$L12 -> 0 | O12: =IFERROR( IF(L12 > J12, ((M12 - I12) / E12) * F12 * (L12 - J12), ((I12 - K12) / E12) * F12 * (J12 - L12) ), 0) -> 0 | P12: =IFERROR((MIN(J12,L12) * ((M12 - K12) / E12) * F12)-V12*Q12, 0) -> 648.6 | Q12: =MIN($J12,$L12)*$G12 -> 24 | R12: =((Mapping!$M12 - Mapping!$K12) / Mapping!$E12 * Mapping!$F12) * (MIN(Mapping!$J12, Mapping!$L12)) -> 684.6 | S12: =IFERROR(INDEX(#REF!, MATCH(Mapping!C12,#REF!, 0)), "") | T12: =IF(N12>0, (S12-K12)*F12/E12*N12, (S12-M12)*F12/E12*N12) -> #VALUE! | U12: =IFERROR(INDEX(Ref!E:E, MATCH(D12, Ref!B:B, 0)),5) -> 0 | V12: =IFERROR(INDEX(Ref!F:F, MATCH(D12, Ref!B:B, 0)),1.5) -> 1.5
C13: ZC Jul25-Sep25 Calendar | D13: {=UPPER(_xlfn.TEXTJOIN("", TRUE, IF(ISNUMBER(FIND(MID(LEFT(C13, FIND(" ", C13 & " ") - 1), ROW(INDIRECT("1:" & LEN(LEFT(C13, FIND(" ", C13 & " ") - 1)))), 1), "ABCDEFGHIJKLMNOPQRSTUVWXYZabcdefghijklmnopqrstuvwxyz")), MID(LEFT(C13, FIND(" ", C13 & " ") - 1), ROW(INDIRECT("1:" & LEN(LEFT(C13, FIND(" ", C13 & " ") - 1)))), 1), "")))} -> ZC | E13: =INDEX(Ref!C:C, MATCH(Mapping!D13, Ref!$B:$B,0)) -> 0.25 | F13: =INDEX(Ref!D:D, MATCH(Mapping!D13, Ref!$B:$B,0)) -> 12.5 | G13: {=IFERROR(_xlfn.SWITCH(LOWER(TRIM(RIGHT(SUBSTITUTE(C13," ",REPT(" ",99)),99))),"fly",4,"dfly",8,"calendar",2,"box",4,4),4)} -> 2 | H13: ASE | I13: =RTD("tt.rtd",,RTD("tt.rtd",,"Inst",H13,$C13),I$2) -> #N/A | J13: {=SUM(IF(('Fill Book'!$F$4:$F$10084="B")*('Fill Book'!$E$4:$E$10084=Mapping!C13),'Fill Book'!$G$4:$G$10084))} -> 1 | K13: {=IFERROR( SUMPRODUCT( ('Fill Book'!$F$4:$F$10084="B") * ('Fill Book'!$E$4:$E$10084=Mapping!C13), 'Fill Book'!$G$4:$G$10084, 'Fill Book'!$H$4:$H$10084 ) / SUMIFS( 'Fill Book'!$G$4:$G$10084, 'Fill Book'!$F$4:$F$10084, "B", 'Fill Book'!$E$4:$E$10084, Mapping!C13 ), "" )} -> 0 | L13: =SUMIFS('Fill Book'!$G$4:$G$10084, 'Fill Book'!$F$4:$F$10084, "S", 'Fill Book'!$E$4:$E$10084, Mapping!C13) -> 1 | M13: {=IFERROR( SUMPRODUCT( ('Fill Book'!$F$4:$F$10084="S") * ('Fill Book'!$E$4:$E$10084=Mapping!C13), 'Fill Book'!$G$4:$G$10084, 'Fill Book'!$H$4:$H$10084 ) / SUMIFS( 'Fill Book'!$G$4:$G$10084, 'Fill Book'!$F$4:$F$10084, "S", 'Fill Book'!$E$4:$E$10084, Mapping!C13 ), "" )} -> 0 | N13: =$J13-$L13 -> 0 | O13: =IFERROR( IF(L13 > J13, ((M13 - I13) / E13) * F13 * (L13 - J13), ((I13 - K13) / E13) * F13 * (J13 - L13) ), 0) -> 0 | P13: =IFERROR((MIN(J13,L13) * ((M13 - K13) / E13) * F13)-V13*Q13, 0) -> -3 | Q13: =MIN($J13,$L13)*$G13 -> 2 | R13: =((Mapping!$M13 - Mapping!$K13) / Mapping!$E13 * Mapping!$F13) * (MIN(Mapping!$J13, Mapping!$L13)) -> 0 | S13: =IFERROR(INDEX(#REF!, MATCH(Mapping!C13,#REF!, 0)), "") | T13: =IF(N13>0, (S13-K13)*F13/E13*N13, (S13-M13)*F13/E13*N13) -> #VALUE! | U13: =IFERROR(INDEX(Ref!E:E, MATCH(D13, Ref!B:B, 0)),5) -> 1 | V13: =IFERROR(INDEX(Ref!F:F, MATCH(D13, Ref!B:B, 0)),1.5) -> 1.5
C14: NG Aug25-Sep25 Calendar | D14: {=UPPER(_xlfn.TEXTJOIN("", TRUE, IF(ISNUMBER(FIND(MID(LEFT(C14, FIND(" ", C14 & " ") - 1), ROW(INDIRECT("1:" & LEN(LEFT(C14, FIND(" ", C14 & " ") - 1)))), 1), "ABCDEFGHIJKLMNOPQRSTUVWXYZabcdefghijklmnopqrstuvwxyz")), MID(LEFT(C14, FIND(" ", C14 & " ") - 1), ROW(INDIRECT("1:" & LEN(LEFT(C14, FIND(" ", C14 & " ") - 1)))), 1), "")))} -> NG | E14: =INDEX(Ref!C:C, MATCH(Mapping!D14, Ref!$B:$B,0)) -> 0.001 | F14: =INDEX(Ref!D:D, MATCH(Mapping!D14, Ref!$B:$B,0)) -> 10 | G14: {=IFERROR(_xlfn.SWITCH(LOWER(TRIM(RIGHT(SUBSTITUTE(C14," ",REPT(" ",99)),99))),"fly",4,"dfly",8,"calendar",2,"box",4,4),4)} -> 2 | H14: ASE | I14: =RTD("tt.rtd",,RTD("tt.rtd",,"Inst",H14,$C14),I$2) -> #N/A | J14: {=SUM(IF(('Fill Book'!$F$4:$F$10084="B")*('Fill Book'!$E$4:$E$10084=Mapping!C14),'Fill Book'!$G$4:$G$10084))} -> 5 | K14: {=IFERROR( SUMPRODUCT( ('Fill Book'!$F$4:$F$10084="B") * ('Fill Book'!$E$4:$E$10084=Mapping!C14), 'Fill Book'!$G$4:$G$10084, 'Fill Book'!$H$4:$H$10084 ) / SUMIFS( 'Fill Book'!$G$4:$G$10084, 'Fill Book'!$F$4:$F$10084, "B", 'Fill Book'!$E$4:$E$10084, Mapping!C14 ), "" )} -> -0.0282 | L14: =SUMIFS('Fill Book'!$G$4:$G$10084, 'Fill Book'!$F$4:$F$10084, "S", 'Fill Book'!$E$4:$E$10084, Mapping!C14) -> 5 | M14: {=IFERROR( SUMPRODUCT( ('Fill Book'!$F$4:$F$10084="S") * ('Fill Book'!$E$4:$E$10084=Mapping!C14), 'Fill Book'!$G$4:$G$10084, 'Fill Book'!$H$4:$H$10084 ) / SUMIFS( 'Fill Book'!$G$4:$G$10084, 'Fill Book'!$F$4:$F$10084, "S", 'Fill Book'!$E$4:$E$10084, Mapping!C14 ), "" )} -> -0.0324 | N14: =$J14-$L14 -> 0 | O14: =IFERROR( IF(L14 > J14, ((M14 - I14) / E14) * F14 * (L14 - J14), ((I14 - K14) / E14) * F14 * (J14 - L14) ), 0) -> 0 | P14: =IFERROR((MIN(J14,L14) * ((M14 - K14) / E14) * F14)-V14*Q14, 0) -> -225 | Q14: =MIN($J14,$L14)*$G14 -> 10 | R14: =((Mapping!$M14 - Mapping!$K14) / Mapping!$E14 * Mapping!$F14) * (MIN(Mapping!$J14, Mapping!$L14)) -> -210 | S14: =IFERROR(INDEX(#REF!, MATCH(Mapping!C14,#REF!, 0)), "") | T14: =IF(N14>0, (S14-K14)*F14/E14*N14, (S14-M14)*F14/E14*N14) -> #VALUE! | U14: =IFERROR(INDEX(Ref!E:E, MATCH(D14, Ref!B:B, 0)),5) -> 0 | V14: =IFERROR(INDEX(Ref!F:F, MATCH(D14, Ref!B:B, 0)),1.5) -> 1.5
C15: NG Sep25-Oct25 Calendar | D15: {=UPPER(_xlfn.TEXTJOIN("", TRUE, IF(ISNUMBER(FIND(MID(LEFT(C15, FIND(" ", C15 & " ") - 1), ROW(INDIRECT("1:" & LEN(LEFT(C15, FIND(" ", C15 & " ") - 1)))), 1), "ABCDEFGHIJKLMNOPQRSTUVWXYZabcdefghijklmnopqrstuvwxyz")), MID(LEFT(C15, FIND(" ", C15 & " ") - 1), ROW(INDIRECT("1:" & LEN(LEFT(C15, FIND(" ", C15 & " ") - 1)))), 1), "")))} -> NG | E15: =INDEX(Ref!C:C, MATCH(Mapping!D15, Ref!$B:$B,0)) -> 0.001 | F15: =INDEX(Ref!D:D, MATCH(Mapping!D15, Ref!$B:$B,0)) -> 10 | G15: {=IFERROR(_xlfn.SWITCH(LOWER(TRIM(RIGHT(SUBSTITUTE(C15," ",REPT(" ",99)),99))),"fly",4,"dfly",8,"calendar",2,"box",4,4),4)} -> 2 | H15: ASE | I15: =RTD("tt.rtd",,RTD("tt.rtd",,"Inst",H15,$C15),I$2) -> #N/A | J15: {=SUM(IF(('Fill Book'!$F$4:$F$10084="B")*('Fill Book'!$E$4:$E$10084=Mapping!C15),'Fill Book'!$G$4:$G$10084))} -> 1 | K15: {=IFERROR( SUMPRODUCT( ('Fill Book'!$F$4:$F$10084="B") * ('Fill Book'!$E$4:$E$10084=Mapping!C15), 'Fill Book'!$G$4:$G$10084, 'Fill Book'!$H$4:$H$10084 ) / SUMIFS( 'Fill Book'!$G$4:$G$10084, 'Fill Book'!$F$4:$F$10084, "B", 'Fill Book'!$E$4:$E$10084, Mapping!C15 ), "" )} -> -0.119 | L15: =SUMIFS('Fill Book'!$G$4:$G$10084, 'Fill Book'!$F$4:$F$10084, "S", 'Fill Book'!$E$4:$E$10084, Mapping!C15) -> 0 | M15: {=IFERROR( SUMPRODUCT( ('Fill Book'!$F$4:$F$10084="S") * ('Fill Book'!$E$4:$E$10084=Mapping!C15), 'Fill Book'!$G$4:$G$10084, 'Fill Book'!$H$4:$H$10084 ) / SUMIFS( 'Fill Book'!$G$4:$G$10084, 'Fill Book'!$F$4:$F$10084, "S", 'Fill Book'!$E$4:$E$10084, Mapping!C15 ), "" )} | N15: =$J15-$L15 -> 1 | O15: =IFERROR( IF(L15 > J15, ((M15 - I15) / E15) * F15 * (L15 - J15), ((I15 - K15) / E15) * F15 * (J15 - L15) ), 0) -> 0 | P15: =IFERROR((MIN(J15,L15) * ((M15 - K15) / E15) * F15)-V15*Q15, 0) -> 0 | Q15: =MIN($J15,$L15)*$G15 -> 0 | R15: =((Mapping!$M15 - Mapping!$K15) / Mapping!$E15 * Mapping!$F15) * (MIN(Mapping!$J15, Mapping!$L15)) -> #VALUE! | S15: =IFERROR(INDEX(#REF!, MATCH(Mapping!C15,#REF!, 0)), "") | T15: =IF(N15>0, (S15-K15)*F15/E15*N15, (S15-M15)*F15/E15*N15) -> #VALUE! | U15: =IFERROR(INDEX(Ref!E:E, MATCH(D15, Ref!B:B, 0)),5) -> 0 | V15: =IFERROR(INDEX(Ref!F:F, MATCH(D15, Ref!B:B, 0)),1.5) -> 1.5
D16: {=UPPER(_xlfn.TEXTJOIN("", TRUE, IF(ISNUMBER(FIND(MID(LEFT(C16, FIND(" ", C16 & " ") - 1), ROW(INDIRECT("1:" & LEN(LEFT(C16, FIND(" ", C16 & " ") - 1)))), 1), "ABCDEFGHIJKLMNOPQRSTUVWXYZabcdefghijklmnopqrstuvwxyz")), MID(LEFT(C16, FIND(" ", C16 & " ") - 1), ROW(INDIRECT("1:" & LEN(LEFT(C16, FIND(" ", C16 & " ") - 1)))), 1), "")))} | E16: =INDEX(Ref!C:C, MATCH(Mapping!D16, Ref!$B:$B,0)) -> #N/A | F16: =INDEX(Ref!D:D, MATCH(Mapping!D16, Ref!$B:$B,0)) -> #N/A | G16: {=IFERROR(_xlfn.SWITCH(LOWER(TRIM(RIGHT(SUBSTITUTE(C16," ",REPT(" ",99)),99))),"fly",4,"dfly",8,"calendar",2,"box",4,4),4)} -> 4 | H16: ASE | I16: =RTD("tt.rtd",,RTD("tt.rtd",,"Inst",H16,$C16),I$2) | J16: {=SUM(IF(('Fill Book'!$F$4:$F$10084="B")*('Fill Book'!$E$4:$E$10084=Mapping!C16),'Fill Book'!$G$4:$G$10084))} -> 0 | K16: {=IFERROR( SUMPRODUCT( ('Fill Book'!$F$4:$F$10084="B") * ('Fill Book'!$E$4:$E$10084=Mapping!C16), 'Fill Book'!$G$4:$G$10084, 'Fill Book'!$H$4:$H$10084 ) / SUMIFS( 'Fill Book'!$G$4:$G$10084, 'Fill Book'!$F$4:$F$10084, "B", 'Fill Book'!$E$4:$E$10084, Mapping!C16 ), "" )} | L16: =SUMIFS('Fill Book'!$G$4:$G$10084, 'Fill Book'!$F$4:$F$10084, "S", 'Fill Book'!$E$4:$E$10084, Mapping!C16) -> 0 | M16: {=IFERROR( SUMPRODUCT( ('Fill Book'!$F$4:$F$10084="S") * ('Fill Book'!$E$4:$E$10084=Mapping!C16), 'Fill Book'!$G$4:$G$10084, 'Fill Book'!$H$4:$H$10084 ) / SUMIFS( 'Fill Book'!$G$4:$G$10084, 'Fill Book'!$F$4:$F$10084, "S", 'Fill Book'!$E$4:$E$10084, Mapping!C16 ), "" )} | N16: =$J16-$L16 -> 0 | O16: =IFERROR( IF(L16 > J16, ((M16 - I16) / E16) * F16 * (L16 - J16), ((I16 - K16) / E16) * F16 * (J16 - L16) ), 0) -> 0 | P16: =IFERROR((MIN(J16,L16) * ((M16 - K16) / E16) * F16)-V16*Q16, 0) -> 0 | Q16: =MIN($J16,$L16)*$G16 -> 0 | R16: =((Mapping!$M16 - Mapping!$K16) / Mapping!$E16 * Mapping!$F16) * (MIN(Mapping!$J16, Mapping!$L16)) -> #VALUE! | S16: =IFERROR(INDEX(#REF!, MATCH(Mapping!C16,#REF!, 0)), "") | T16: =IF(N16>0, (S16-K16)*F16/E16*N16, (S16-M16)*F16/E16*N16) -> #VALUE! | U16: =IFERROR(INDEX(Ref!E:E, MATCH(D16, Ref!B:B, 0)),5) -> 5 | V16: =IFERROR(INDEX(Ref!F:F, MATCH(D16, Ref!B:B, 0)),1.5) -> 1.5
D17: {=UPPER(_xlfn.TEXTJOIN("", TRUE, IF(ISNUMBER(FIND(MID(LEFT(C17, FIND(" ", C17 & " ") - 1), ROW(INDIRECT("1:" & LEN(LEFT(C17, FIND(" ", C17 & " ") - 1)))), 1), "ABCDEFGHIJKLMNOPQRSTUVWXYZabcdefghijklmnopqrstuvwxyz")), MID(LEFT(C17, FIND(" ", C17 & " ") - 1), ROW(INDIRECT("1:" & LEN(LEFT(C17, FIND(" ", C17 & " ") - 1)))), 1), "")))} | E17: =INDEX(Ref!C:C, MATCH(Mapping!D17, Ref!$B:$B,0)) -> #N/A | F17: =INDEX(Ref!D:D, MATCH(Mapping!D17, Ref!$B:$B,0)) -> #N/A | G17: {=IFERROR(_xlfn.SWITCH(LOWER(TRIM(RIGHT(SUBSTITUTE(C17," ",REPT(" ",99)),99))),"fly",4,"dfly",8,"calendar",2,"box",4,4),4)} -> 4 | H17: ASE | I17: =RTD("tt.rtd",,RTD("tt.rtd",,"Inst",H17,$C17),I$2) | J17: {=SUM(IF(('Fill Book'!$F$4:$F$10084="B")*('Fill Book'!$E$4:$E$10084=Mapping!C17),'Fill Book'!$G$4:$G$10084))} -> 0 | K17: {=IFERROR( SUMPRODUCT( ('Fill Book'!$F$4:$F$10084="B") * ('Fill Book'!$E$4:$E$10084=Mapping!C17), 'Fill Book'!$G$4:$G$10084, 'Fill Book'!$H$4:$H$10084 ) / SUMIFS( 'Fill Book'!$G$4:$G$10084, 'Fill Book'!$F$4:$F$10084, "B", 'Fill Book'!$E$4:$E$10084, Mapping!C17 ), "" )} | L17: =SUMIFS('Fill Book'!$G$4:$G$10084, 'Fill Book'!$F$4:$F$10084, "S", 'Fill Book'!$E$4:$E$10084, Mapping!C17) -> 0 | M17: {=IFERROR( SUMPRODUCT( ('Fill Book'!$F$4:$F$10084="S") * ('Fill Book'!$E$4:$E$10084=Mapping!C17), 'Fill Book'!$G$4:$G$10084, 'Fill Book'!$H$4:$H$10084 ) / SUMIFS( 'Fill Book'!$G$4:$G$10084, 'Fill Book'!$F$4:$F$10084, "S", 'Fill Book'!$E$4:$E$10084, Mapping!C17 ), "" )} | N17: =$J17-$L17 -> 0 | O17: =IFERROR( IF(L17 > J17, ((M17 - I17) / E17) * F17 * (L17 - J17), ((I17 - K17) / E17) * F17 * (J17 - L17) ), 0) -> 0 | P17: =IFERROR((MIN(J17,L17) * ((M17 - K17) / E17) * F17)-V17*Q17, 0) -> 0 | Q17: =MIN($J17,$L17)*$G17 -> 0 | R17: =((Mapping!$M17 - Mapping!$K17) / Mapping!$E17 * Mapping!$F17) * (MIN(Mapping!$J17, Mapping!$L17)) -> #VALUE! | S17: =IFERROR(INDEX(#REF!, MATCH(Mapping!C17,#REF!, 0)), "") | T17: =IF(N17>0, (S17-K17)*F17/E17*N17, (S17-M17)*F17/E17*N17) -> #VALUE! | U17: =IFERROR(INDEX(Ref!E:E, MATCH(D17, Ref!B:B, 0)),5) -> 5 | V17: =IFERROR(INDEX(Ref!F:F, MATCH(D17, Ref!B:B, 0)),1.5) -> 1.5
D18: {=UPPER(_xlfn.TEXTJOIN("", TRUE, IF(ISNUMBER(FIND(MID(LEFT(C18, FIND(" ", C18 & " ") - 1), ROW(INDIRECT("1:" & LEN(LEFT(C18, FIND(" ", C18 & " ") - 1)))), 1), "ABCDEFGHIJKLMNOPQRSTUVWXYZabcdefghijklmnopqrstuvwxyz")), MID(LEFT(C18, FIND(" ", C18 & " ") - 1), ROW(INDIRECT("1:" & LEN(LEFT(C18, FIND(" ", C18 & " ") - 1)))), 1), "")))} | E18: =INDEX(Ref!C:C, MATCH(Mapping!D18, Ref!$B:$B,0)) -> #N/A | F18: =INDEX(Ref!D:D, MATCH(Mapping!D18, Ref!$B:$B,0)) -> #N/A | G18: {=IFERROR(_xlfn.SWITCH(LOWER(TRIM(RIGHT(SUBSTITUTE(C18," ",REPT(" ",99)),99))),"fly",4,"dfly",8,"calendar",2,"box",4,4),4)} -> 4 | H18: ASE | I18: =RTD("tt.rtd",,RTD("tt.rtd",,"Inst",H18,$C18),I$2) | J18: {=SUM(IF(('Fill Book'!$F$4:$F$10084="B")*('Fill Book'!$E$4:$E$10084=Mapping!C18),'Fill Book'!$G$4:$G$10084))} -> 0 | K18: {=IFERROR( SUMPRODUCT( ('Fill Book'!$F$4:$F$10084="B") * ('Fill Book'!$E$4:$E$10084=Mapping!C18), 'Fill Book'!$G$4:$G$10084, 'Fill Book'!$H$4:$H$10084 ) / SUMIFS( 'Fill Book'!$G$4:$G$10084, 'Fill Book'!$F$4:$F$10084, "B", 'Fill Book'!$E$4:$E$10084, Mapping!C18 ), "" )} | L18: =SUMIFS('Fill Book'!$G$4:$G$10084, 'Fill Book'!$F$4:$F$10084, "S", 'Fill Book'!$E$4:$E$10084, Mapping!C18) -> 0 | M18: {=IFERROR( SUMPRODUCT( ('Fill Book'!$F$4:$F$10084="S") * ('Fill Book'!$E$4:$E$10084=Mapping!C18), 'Fill Book'!$G$4:$G$10084, 'Fill Book'!$H$4:$H$10084 ) / SUMIFS( 'Fill Book'!$G$4:$G$10084, 'Fill Book'!$F$4:$F$10084, "S", 'Fill Book'!$E$4:$E$10084, Mapping!C18 ), "" )} | N18: =$J18-$L18 -> 0 | O18: =IFERROR( IF(L18 > J18, ((M18 - I18) / E18) * F18 * (L18 - J18), ((I18 - K18) / E18) * F18 * (J18 - L18) ), 0) -> 0 | P18: =IFERROR((MIN(J18,L18) * ((M18 - K18) / E18) * F18)-V18*Q18, 0) -> 0 | Q18: =MIN($J18,$L18)*$G18 -> 0 | R18: =((Mapping!$M18 - Mapping!$K18) / Mapping!$E18 * Mapping!$F18) * (MIN(Mapping!$J18, Mapping!$L18)) -> #VALUE! | S18: =IFERROR(INDEX(#REF!, MATCH(Mapping!C18,#REF!, 0)), "") | T18: =IF(N18>0, (S18-K18)*F18/E18*N18, (S18-M18)*F18/E18*N18) -> #VALUE! | U18: =IFERROR(INDEX(Ref!E:E, MATCH(D18, Ref!B:B, 0)),5) -> 5 | V18: =IFERROR(INDEX(Ref!F:F, MATCH(D18, Ref!B:B, 0)),1.5) -> 1.5
D19: {=UPPER(_xlfn.TEXTJOIN("", TRUE, IF(ISNUMBER(FIND(MID(LEFT(C19, FIND(" ", C19 & " ") - 1), ROW(INDIRECT("1:" & LEN(LEFT(C19, FIND(" ", C19 & " ") - 1)))), 1), "ABCDEFGHIJKLMNOPQRSTUVWXYZabcdefghijklmnopqrstuvwxyz")), MID(LEFT(C19, FIND(" ", C19 & " ") - 1), ROW(INDIRECT("1:" & LEN(LEFT(C19, FIND(" ", C19 & " ") - 1)))), 1), "")))} | E19: =INDEX(Ref!C:C, MATCH(Mapping!D19, Ref!$B:$B,0)) -> #N/A | F19: =INDEX(Ref!D:D, MATCH(Mapping!D19, Ref!$B:$B,0)) -> #N/A | G19: {=IFERROR(_xlfn.SWITCH(LOWER(TRIM(RIGHT(SUBSTITUTE(C19," ",REPT(" ",99)),99))),"fly",4,"dfly",8,"calendar",2,"box",4,4),4)} -> 4 | H19: ASE | I19: =RTD("tt.rtd",,RTD("tt.rtd",,"Inst",H19,$C19),I$2) | J19: {=SUM(IF(('Fill Book'!$F$4:$F$10084="B")*('Fill Book'!$E$4:$E$10084=Mapping!C19),'Fill Book'!$G$4:$G$10084))} -> 0 | K19: {=IFERROR( SUMPRODUCT( ('Fill Book'!$F$4:$F$10084="B") * ('Fill Book'!$E$4:$E$10084=Mapping!C19), 'Fill Book'!$G$4:$G$10084, 'Fill Book'!$H$4:$H$10084 ) / SUMIFS( 'Fill Book'!$G$4:$G$10084, 'Fill Book'!$F$4:$F$10084, "B", 'Fill Book'!$E$4:$E$10084, Mapping!C19 ), "" )} | L19: =SUMIFS('Fill Book'!$G$4:$G$10084, 'Fill Book'!$F$4:$F$10084, "S", 'Fill Book'!$E$4:$E$10084, Mapping!C19) -> 0 | M19: {=IFERROR( SUMPRODUCT( ('Fill Book'!$F$4:$F$10084="S") * ('Fill Book'!$E$4:$E$10084=Mapping!C19), 'Fill Book'!$G$4:$G$10084, 'Fill Book'!$H$4:$H$10084 ) / SUMIFS( 'Fill Book'!$G$4:$G$10084, 'Fill Book'!$F$4:$F$10084, "S", 'Fill Book'!$E$4:$E$10084, Mapping!C19 ), "" )} | N19: =$J19-$L19 -> 0 | O19: =IFERROR( IF(L19 > J19, ((M19 - I19) / E19) * F19 * (L19 - J19), ((I19 - K19) / E19) * F19 * (J19 - L19) ), 0) -> 0 | P19: =IFERROR((MIN(J19,L19) * ((M19 - K19) / E19) * F19)-V19*Q19, 0) -> 0 | Q19: =MIN($J19,$L19)*$G19 -> 0 | R19: =((Mapping!$M19 - Mapping!$K19) / Mapping!$E19 * Mapping!$F19) * (MIN(Mapping!$J19, Mapping!$L19)) -> #VALUE! | S19: =IFERROR(INDEX(#REF!, MATCH(Mapping!C19,#REF!, 0)), "") | T19: =IF(N19>0, (S19-K19)*F19/E19*N19, (S19-M19)*F19/E19*N19) -> #VALUE! | U19: =IFERROR(INDEX(Ref!E:E, MATCH(D19, Ref!B:B, 0)),5) -> 5 | V19: =IFERROR(INDEX(Ref!F:F, MATCH(D19, Ref!B:B, 0)),1.5) -> 1.5
D20: {=UPPER(_xlfn.TEXTJOIN("", TRUE, IF(ISNUMBER(FIND(MID(LEFT(C20, FIND(" ", C20 & " ") - 1), ROW(INDIRECT("1:" & LEN(LEFT(C20, FIND(" ", C20 & " ") - 1)))), 1), "ABCDEFGHIJKLMNOPQRSTUVWXYZabcdefghijklmnopqrstuvwxyz")), MID(LEFT(C20, FIND(" ", C20 & " ") - 1), ROW(INDIRECT("1:" & LEN(LEFT(C20, FIND(" ", C20 & " ") - 1)))), 1), "")))} | E20: =INDEX(Ref!C:C, MATCH(Mapping!D20, Ref!$B:$B,0)) -> #N/A | F20: =INDEX(Ref!D:D, MATCH(Mapping!D20, Ref!$B:$B,0)) -> #N/A | G20: {=IFERROR(_xlfn.SWITCH(LOWER(TRIM(RIGHT(SUBSTITUTE(C20," ",REPT(" ",99)),99))),"fly",4,"dfly",8,"calendar",2,"box",4,4),4)} -> 4 | H20: ASE | I20: =RTD("tt.rtd",,RTD("tt.rtd",,"Inst",H20,$C20),I$2) | J20: {=SUM(IF(('Fill Book'!$F$4:$F$10084="B")*('Fill Book'!$E$4:$E$10084=Mapping!C20),'Fill Book'!$G$4:$G$10084))} -> 0 | K20: {=IFERROR( SUMPRODUCT( ('Fill Book'!$F$4:$F$10084="B") * ('Fill Book'!$E$4:$E$10084=Mapping!C20), 'Fill Book'!$G$4:$G$10084, 'Fill Book'!$H$4:$H$10084 ) / SUMIFS( 'Fill Book'!$G$4:$G$10084, 'Fill Book'!$F$4:$F$10084, "B", 'Fill Book'!$E$4:$E$10084, Mapping!C20 ), "" )} | L20: =SUMIFS('Fill Book'!$G$4:$G$10084, 'Fill Book'!$F$4:$F$10084, "S", 'Fill Book'!$E$4:$E$10084, Mapping!C20) -> 0 | M20: {=IFERROR( SUMPRODUCT( ('Fill Book'!$F$4:$F$10084="S") * ('Fill Book'!$E$4:$E$10084=Mapping!C20), 'Fill Book'!$G$4:$G$10084, 'Fill Book'!$H$4:$H$10084 ) / SUMIFS( 'Fill Book'!$G$4:$G$10084, 'Fill Book'!$F$4:$F$10084, "S", 'Fill Book'!$E$4:$E$10084, Mapping!C20 ), "" )} | N20: =$J20-$L20 -> 0 | O20: =IFERROR( IF(L20 > J20, ((M20 - I20) / E20) * F20 * (L20 - J20), ((I20 - K20) / E20) * F20 * (J20 - L20) ), 0) -> 0 | P20: =IFERROR((MIN(J20,L20) * ((M20 - K20) / E20) * F20)-V20*Q20, 0) -> 0 | Q20: =MIN($J20,$L20)*$G20 -> 0 | R20: =((Mapping!$M20 - Mapping!$K20) / Mapping!$E20 * Mapping!$F20) * (MIN(Mapping!$J20, Mapping!$L20)) -> #VALUE! | S20: =IFERROR(INDEX(#REF!, MATCH(Mapping!C20,#REF!, 0)), "") | T20: =IF(N20>0, (S20-K20)*F20/E20*N20, (S20-M20)*F20/E20*N20) -> #VALUE! | U20: =IFERROR(INDEX(Ref!E:E, MATCH(D20, Ref!B:B, 0)),5) -> 5 | V20: =IFERROR(INDEX(Ref!F:F, MATCH(D20, Ref!B:B, 0)),1.5) -> 1.5
D21: {=UPPER(_xlfn.TEXTJOIN("", TRUE, IF(ISNUMBER(FIND(MID(LEFT(C21, FIND(" ", C21 & " ") - 1), ROW(INDIRECT("1:" & LEN(LEFT(C21, FIND(" ", C21 & " ") - 1)))), 1), "ABCDEFGHIJKLMNOPQRSTUVWXYZabcdefghijklmnopqrstuvwxyz")), MID(LEFT(C21, FIND(" ", C21 & " ") - 1), ROW(INDIRECT("1:" & LEN(LEFT(C21, FIND(" ", C21 & " ") - 1)))), 1), "")))} | E21: =INDEX(Ref!C:C, MATCH(Mapping!D21, Ref!$B:$B,0)) -> #N/A | F21: =INDEX(Ref!D:D, MATCH(Mapping!D21, Ref!$B:$B,0)) -> #N/A | G21: {=IFERROR(_xlfn.SWITCH(LOWER(TRIM(RIGHT(SUBSTITUTE(C21," ",REPT(" ",99)),99))),"fly",4,"dfly",8,"calendar",2,"box",4,4),4)} -> 4 | H21: ASE | I21: =RTD("tt.rtd",,RTD("tt.rtd",,"Inst",H21,$C21),I$2) | J21: {=SUM(IF(('Fill Book'!$F$4:$F$10084="B")*('Fill Book'!$E$4:$E$10084=Mapping!C21),'Fill Book'!$G$4:$G$10084))} -> 0 | K21: {=IFERROR( SUMPRODUCT( ('Fill Book'!$F$4:$F$10084="B") * ('Fill Book'!$E$4:$E$10084=Mapping!C21), 'Fill Book'!$G$4:$G$10084, 'Fill Book'!$H$4:$H$10084 ) / SUMIFS( 'Fill Book'!$G$4:$G$10084, 'Fill Book'!$F$4:$F$10084, "B", 'Fill Book'!$E$4:$E$10084, Mapping!C21 ), "" )} | L21: =SUMIFS('Fill Book'!$G$4:$G$10084, 'Fill Book'!$F$4:$F$10084, "S", 'Fill Book'!$E$4:$E$10084, Mapping!C21) -> 0 | M21: {=IFERROR( SUMPRODUCT( ('Fill Book'!$F$4:$F$10084="S") * ('Fill Book'!$E$4:$E$10084=Mapping!C21), 'Fill Book'!$G$4:$G$10084, 'Fill Book'!$H$4:$H$10084 ) / SUMIFS( 'Fill Book'!$G$4:$G$10084, 'Fill Book'!$F$4:$F$10084, "S", 'Fill Book'!$E$4:$E$10084, Mapping!C21 ), "" )} | N21: =$J21-$L21 -> 0 | O21: =IFERROR( IF(L21 > J21, ((M21 - I21) / E21) * F21 * (L21 - J21), ((I21 - K21) / E21) * F21 * (J21 - L21) ), 0) -> 0 | P21: =IFERROR((MIN(J21,L21) * ((M21 - K21) / E21) * F21)-V21*Q21, 0) -> 0 | Q21: =MIN($J21,$L21)*$G21 -> 0 | R21: =((Mapping!$M21 - Mapping!$K21) / Mapping!$E21 * Mapping!$F21) * (MIN(Mapping!$J21, Mapping!$L21)) -> #VALUE! | S21: =IFERROR(INDEX(#REF!, MATCH(Mapping!C21,#REF!, 0)), "") | T21: =IF(N21>0, (S21-K21)*F21/E21*N21, (S21-M21)*F21/E21*N21) -> #VALUE! | U21: =IFERROR(INDEX(Ref!E:E, MATCH(D21, Ref!B:B, 0)),5) -> 5 | V21: =IFERROR(INDEX(Ref!F:F, MATCH(D21, Ref!B:B, 0)),1.5) -> 1.5
D22: {=UPPER(_xlfn.TEXTJOIN("", TRUE, IF(ISNUMBER(FIND(MID(LEFT(C22, FIND(" ", C22 & " ") - 1), ROW(INDIRECT("1:" & LEN(LEFT(C22, FIND(" ", C22 & " ") - 1)))), 1), "ABCDEFGHIJKLMNOPQRSTUVWXYZabcdefghijklmnopqrstuvwxyz")), MID(LEFT(C22, FIND(" ", C22 & " ") - 1), ROW(INDIRECT("1:" & LEN(LEFT(C22, FIND(" ", C22 & " ") - 1)))), 1), "")))} | E22: =INDEX(Ref!C:C, MATCH(Mapping!D22, Ref!$B:$B,0)) -> #N/A | F22: =INDEX(Ref!D:D, MATCH(Mapping!D22, Ref!$B:$B,0)) -> #N/A | G22: {=IFERROR(_xlfn.SWITCH(LOWER(TRIM(RIGHT(SUBSTITUTE(C22," ",REPT(" ",99)),99))),"fly",4,"dfly",8,"calendar",2,"box",4,4),4)} -> 4 | H22: ASE | I22: =RTD("tt.rtd",,RTD("tt.rtd",,"Inst",H22,$C22),I$2) | J22: {=SUM(IF(('Fill Book'!$F$4:$F$10084="B")*('Fill Book'!$E$4:$E$10084=Mapping!C22),'Fill Book'!$G$4:$G$10084))} -> 0 | K22: {=IFERROR( SUMPRODUCT( ('Fill Book'!$F$4:$F$10084="B") * ('Fill Book'!$E$4:$E$10084=Mapping!C22), 'Fill Book'!$G$4:$G$10084, 'Fill Book'!$H$4:$H$10084 ) / SUMIFS( 'Fill Book'!$G$4:$G$10084, 'Fill Book'!$F$4:$F$10084, "B", 'Fill Book'!$E$4:$E$10084, Mapping!C22 ), "" )} | L22: =SUMIFS('Fill Book'!$G$4:$G$10084, 'Fill Book'!$F$4:$F$10084, "S", 'Fill Book'!$E$4:$E$10084, Mapping!C22) -> 0 | M22: {=IFERROR( SUMPRODUCT( ('Fill Book'!$F$4:$F$10084="S") * ('Fill Book'!$E$4:$E$10084=Mapping!C22), 'Fill Book'!$G$4:$G$10084, 'Fill Book'!$H$4:$H$10084 ) / SUMIFS( 'Fill Book'!$G$4:$G$10084, 'Fill Book'!$F$4:$F$10084, "S", 'Fill Book'!$E$4:$E$10084, Mapping!C22 ), "" )} | N22: =$J22-$L22 -> 0 | O22: =IFERROR( IF(L22 > J22, ((M22 - I22) / E22) * F22 * (L22 - J22), ((I22 - K22) / E22) * F22 * (J22 - L22) ), 0) -> 0 | P22: =IFERROR((MIN(J22,L22) * ((M22 - K22) / E22) * F22)-V22*Q22, 0) -> 0 | Q22: =MIN($J22,$L22)*$G22 -> 0 | R22: =((Mapping!$M22 - Mapping!$K22) / Mapping!$E22 * Mapping!$F22) * (MIN(Mapping!$J22, Mapping!$L22)) -> #VALUE! | S22: =IFERROR(INDEX(#REF!, MATCH(Mapping!C22,#REF!, 0)), "") | T22: =IF(N22>0, (S22-K22)*F22/E22*N22, (S22-M22)*F22/E22*N22) -> #VALUE! | U22: =IFERROR(INDEX(Ref!E:E, MATCH(D22, Ref!B:B, 0)),5) -> 5 | V22: =IFERROR(INDEX(Ref!F:F, MATCH(D22, Ref!B:B, 0)),1.5) -> 1.5
D23: {=UPPER(_xlfn.TEXTJOIN("", TRUE, IF(ISNUMBER(FIND(MID(LEFT(C23, FIND(" ", C23 & " ") - 1), ROW(INDIRECT("1:" & LEN(LEFT(C23, FIND(" ", C23 & " ") - 1)))), 1), "ABCDEFGHIJKLMNOPQRSTUVWXYZabcdefghijklmnopqrstuvwxyz")), MID(LEFT(C23, FIND(" ", C23 & " ") - 1), ROW(INDIRECT("1:" & LEN(LEFT(C23, FIND(" ", C23 & " ") - 1)))), 1), "")))} | E23: =INDEX(Ref!C:C, MATCH(Mapping!D23, Ref!$B:$B,0)) -> #N/A | F23: =INDEX(Ref!D:D, MATCH(Mapping!D23, Ref!$B:$B,0)) -> #N/A | G23: {=IFERROR(_xlfn.SWITCH(LOWER(TRIM(RIGHT(SUBSTITUTE(C23," ",REPT(" ",99)),99))),"fly",4,"dfly",8,"calendar",2,"box",4,4),4)} -> 4 | H23: ASE | I23: =RTD("tt.rtd",,RTD("tt.rtd",,"Inst",H23,$C23),I$2) | J23: {=SUM(IF(('Fill Book'!$F$4:$F$10084="B")*('Fill Book'!$E$4:$E$10084=Mapping!C23),'Fill Book'!$G$4:$G$10084))} -> 0 | K23: {=IFERROR( SUMPRODUCT( ('Fill Book'!$F$4:$F$10084="B") * ('Fill Book'!$E$4:$E$10084=Mapping!C23), 'Fill Book'!$G$4:$G$10084, 'Fill Book'!$H$4:$H$10084 ) / SUMIFS( 'Fill Book'!$G$4:$G$10084, 'Fill Book'!$F$4:$F$10084, "B", 'Fill Book'!$E$4:$E$10084, Mapping!C23 ), "" )} | L23: =SUMIFS('Fill Book'!$G$4:$G$10084, 'Fill Book'!$F$4:$F$10084, "S", 'Fill Book'!$E$4:$E$10084, Mapping!C23) -> 0 | M23: {=IFERROR( SUMPRODUCT( ('Fill Book'!$F$4:$F$10084="S") * ('Fill Book'!$E$4:$E$10084=Mapping!C23), 'Fill Book'!$G$4:$G$10084, 'Fill Book'!$H$4:$H$10084 ) / SUMIFS( 'Fill Book'!$G$4:$G$10084, 'Fill Book'!$F$4:$F$10084, "S", 'Fill Book'!$E$4:$E$10084, Mapping!C23 ), "" )} | N23: =$J23-$L23 -> 0 | O23: =IFERROR( IF(L23 > J23, ((M23 - I23) / E23) * F23 * (L23 - J23), ((I23 - K23) / E23) * F23 * (J23 - L23) ), 0) -> 0 | P23: =IFERROR((MIN(J23,L23) * ((M23 - K23) / E23) * F23)-V23*Q23, 0) -> 0 | Q23: =MIN($J23,$L23)*$G23 -> 0 | R23: =((Mapping!$M23 - Mapping!$K23) / Mapping!$E23 * Mapping!$F23) * (MIN(Mapping!$J23, Mapping!$L23)) -> #VALUE! | S23: =IFERROR(INDEX(#REF!, MATCH(Mapping!C23,#REF!, 0)), "") | T23: =IF(N23>0, (S23-K23)*F23/E23*N23, (S23-M23)*F23/E23*N23) -> #VALUE! | U23: =IFERROR(INDEX(Ref!E:E, MATCH(D23, Ref!B:B, 0)),5) -> 5 | V23: =IFERROR(INDEX(Ref!F:F, MATCH(D23, Ref!B:B, 0)),1.5) -> 1.5
D24: {=UPPER(_xlfn.TEXTJOIN("", TRUE, IF(ISNUMBER(FIND(MID(LEFT(C24, FIND(" ", C24 & " ") - 1), ROW(INDIRECT("1:" & LEN(LEFT(C24, FIND(" ", C24 & " ") - 1)))), 1), "ABCDEFGHIJKLMNOPQRSTUVWXYZabcdefghijklmnopqrstuvwxyz")), MID(LEFT(C24, FIND(" ", C24 & " ") - 1), ROW(INDIRECT("1:" & LEN(LEFT(C24, FIND(" ", C24 & " ") - 1)))), 1), "")))} | E24: =INDEX(Ref!C:C, MATCH(Mapping!D24, Ref!$B:$B,0)) -> #N/A | F24: =INDEX(Ref!D:D, MATCH(Mapping!D24, Ref!$B:$B,0)) -> #N/A | G24: {=IFERROR(_xlfn.SWITCH(LOWER(TRIM(RIGHT(SUBSTITUTE(C24," ",REPT(" ",99)),99))),"fly",4,"dfly",8,"calendar",2,"box",4,4),4)} -> 4 | H24: ASE | I24: =RTD("tt.rtd",,RTD("tt.rtd",,"Inst",H24,$C24),I$2) | J24: {=SUM(IF(('Fill Book'!$F$4:$F$10084="B")*('Fill Book'!$E$4:$E$10084=Mapping!C24),'Fill Book'!$G$4:$G$10084))} -> 0 | K24: {=IFERROR( SUMPRODUCT( ('Fill Book'!$F$4:$F$10084="B") * ('Fill Book'!$E$4:$E$10084=Mapping!C24), 'Fill Book'!$G$4:$G$10084, 'Fill Book'!$H$4:$H$10084 ) / SUMIFS( 'Fill Book'!$G$4:$G$10084, 'Fill Book'!$F$4:$F$10084, "B", 'Fill Book'!$E$4:$E$10084, Mapping!C24 ), "" )} | L24: =SUMIFS('Fill Book'!$G$4:$G$10084, 'Fill Book'!$F$4:$F$10084, "S", 'Fill Book'!$E$4:$E$10084, Mapping!C24) -> 0 | M24: {=IFERROR( SUMPRODUCT( ('Fill Book'!$F$4:$F$10084="S") * ('Fill Book'!$E$4:$E$10084=Mapping!C24), 'Fill Book'!$G$4:$G$10084, 'Fill Book'!$H$4:$H$10084 ) / SUMIFS( 'Fill Book'!$G$4:$G$10084, 'Fill Book'!$F$4:$F$10084, "S", 'Fill Book'!$E$4:$E$10084, Mapping!C24 ), "" )} | N24: =$J24-$L24 -> 0 | O24: =IFERROR( IF(L24 > J24, ((M24 - I24) / E24) * F24 * (L24 - J24), ((I24 - K24) / E24) * F24 * (J24 - L24) ), 0) -> 0 | P24: =IFERROR((MIN(J24,L24) * ((M24 - K24) / E24) * F24)-V24*Q24, 0) -> 0 | Q24: =MIN($J24,$L24)*$G24 -> 0 | R24: =((Mapping!$M24 - Mapping!$K24) / Mapping!$E24 * Mapping!$F24) * (MIN(Mapping!$J24, Mapping!$L24)) -> #VALUE! | S24: =IFERROR(INDEX(#REF!, MATCH(Mapping!C24,#REF!, 0)), "") | T24: =IF(N24>0, (S24-K24)*F24/E24*N24, (S24-M24)*F24/E24*N24) -> #VALUE! | U24: =IFERROR(INDEX(Ref!E:E, MATCH(D24, Ref!B:B, 0)),5) -> 5 | V24: =IFERROR(INDEX(Ref!F:F, MATCH(D24, Ref!B:B, 0)),1.5) -> 1.5
D25: {=UPPER(_xlfn.TEXTJOIN("", TRUE, IF(ISNUMBER(FIND(MID(LEFT(C25, FIND(" ", C25 & " ") - 1), ROW(INDIRECT("1:" & LEN(LEFT(C25, FIND(" ", C25 & " ") - 1)))), 1), "ABCDEFGHIJKLMNOPQRSTUVWXYZabcdefghijklmnopqrstuvwxyz")), MID(LEFT(C25, FIND(" ", C25 & " ") - 1), ROW(INDIRECT("1:" & LEN(LEFT(C25, FIND(" ", C25 & " ") - 1)))), 1), "")))} | E25: =INDEX(Ref!C:C, MATCH(Mapping!D25, Ref!$B:$B,0)) -> #N/A | F25: =INDEX(Ref!D:D, MATCH(Mapping!D25, Ref!$B:$B,0)) -> #N/A | G25: {=IFERROR(_xlfn.SWITCH(LOWER(TRIM(RIGHT(SUBSTITUTE(C25," ",REPT(" ",99)),99))),"fly",4,"dfly",8,"calendar",2,"box",4,4),4)} -> 4 | H25: ASE | I25: =RTD("tt.rtd",,RTD("tt.rtd",,"Inst",H25,$C25),I$2) | J25: {=SUM(IF(('Fill Book'!$F$4:$F$10084="B")*('Fill Book'!$E$4:$E$10084=Mapping!C25),'Fill Book'!$G$4:$G$10084))} -> 0 | K25: {=IFERROR( SUMPRODUCT( ('Fill Book'!$F$4:$F$10084="B") * ('Fill Book'!$E$4:$E$10084=Mapping!C25), 'Fill Book'!$G$4:$G$10084, 'Fill Book'!$H$4:$H$10084 ) / SUMIFS( 'Fill Book'!$G$4:$G$10084, 'Fill Book'!$F$4:$F$10084, "B", 'Fill Book'!$E$4:$E$10084, Mapping!C25 ), "" )} | L25: =SUMIFS('Fill Book'!$G$4:$G$10084, 'Fill Book'!$F$4:$F$10084, "S", 'Fill Book'!$E$4:$E$10084, Mapping!C25) -> 0 | M25: {=IFERROR( SUMPRODUCT( ('Fill Book'!$F$4:$F$10084="S") * ('Fill Book'!$E$4:$E$10084=Mapping!C25), 'Fill Book'!$G$4:$G$10084, 'Fill Book'!$H$4:$H$10084 ) / SUMIFS( 'Fill Book'!$G$4:$G$10084, 'Fill Book'!$F$4:$F$10084, "S", 'Fill Book'!$E$4:$E$10084, Mapping!C25 ), "" )} | N25: =$J25-$L25 -> 0 | O25: =IFERROR( IF(L25 > J25, ((M25 - I25) / E25) * F25 * (L25 - J25), ((I25 - K25) / E25) * F25 * (J25 - L25) ), 0) -> 0 | P25: =IFERROR((MIN(J25,L25) * ((M25 - K25) / E25) * F25)-V25*Q25, 0) -> 0 | Q25: =MIN($J25,$L25)*$G25 -> 0 | R25: =((Mapping!$M25 - Mapping!$K25) / Mapping!$E25 * Mapping!$F25) * (MIN(Mapping!$J25, Mapping!$L25)) -> #VALUE! | S25: =IFERROR(INDEX(#REF!, MATCH(Mapping!C25,#REF!, 0)), "") | T25: =IF(N25>0, (S25-K25)*F25/E25*N25, (S25-M25)*F25/E25*N25) -> #VALUE! | U25: =IFERROR(INDEX(Ref!E:E, MATCH(D25, Ref!B:B, 0)),5) -> 5 | V25: =IFERROR(INDEX(Ref!F:F, MATCH(D25, Ref!B:B, 0)),1.5) -> 1.5
